Fatal | CKSource.CKFinder.Connector.Core.CommandHandler | 2019-03-04 10:17:55.4792 | An unknown error has occured during execution of Thumbnail command.| System.OperationCanceledException: The request was aborted: The request was canceled. ---> System.Net.WebException: The request was aborted: The request was canceled.
   at System.Net.HttpWebRequest.BeginGetResponse(AsyncCallback callback, Object state)
   at System.Threading.Tasks.TaskFactory`1.FromAsyncImpl(Func`3 beginMethod, Func`2 endFunction, Action`1 endAction, Object state, TaskCreationOptions creationOptions)
   at System.Net.WebRequest.<GetResponseAsync>b__78_1()
   at System.Threading.Tasks.Task`1.InnerInvoke()
   at System.Threading.Tasks.Task.Execute()
--- End of stack trace from previous location where exception was thrown ---
   at System.Runtime.ExceptionServices.ExceptionDispatchInfo.Throw()
   at System.Runtime.CompilerServices.TaskAwaiter.HandleNonSuccessAndDebuggerNotification(Task task)
   at Amazon.Runtime.Internal.HttpRequest.<GetResponseAsync>d__16.MoveNext()
   --- End of inner exception stack trace ---
   at Amazon.Runtime.Internal.HttpRequest.<GetResponseAsync>d__16.MoveNext()
--- End of stack trace from previous location where exception was thrown ---
   at System.Runtime.ExceptionServices.ExceptionDispatchInfo.Throw()
   at System.Runtime.CompilerServices.TaskAwaiter.ThrowForNonSuccess(Task task)
   at System.Runtime.CompilerServices.TaskAwaiter.HandleNonSuccessAndDebuggerNotification(Task task)
   at Amazon.Runtime.Internal.HttpHandler`1.<InvokeAsync>d__9`1.MoveNext()
--- End of stack trace from previous location where exception was thrown ---
   at System.Runtime.ExceptionServices.ExceptionDispatchInfo.Throw()
   at System.Runtime.CompilerServices.TaskAwaiter.ThrowForNonSuccess(Task task)
   at System.Runtime.CompilerServices.TaskAwaiter.HandleNonSuccessAndDebuggerNotification(Task task)
   at Amazon.Runtime.Internal.RedirectHandler.<InvokeAsync>d__1`1.MoveNext()
--- End of stack trace from previous location where exception was thrown ---
   at System.Runtime.ExceptionServices.ExceptionDispatchInfo.Throw()
   at System.Runtime.CompilerServices.TaskAwaiter.ThrowForNonSuccess(Task task)
   at System.Runtime.CompilerServices.TaskAwaiter.HandleNonSuccessAndDebuggerNotification(Task task)
   at Amazon.Runtime.Internal.Unmarshaller.<InvokeAsync>d__3`1.MoveNext()
--- End of stack trace from previous location where exception was thrown ---
   at System.Runtime.ExceptionServices.ExceptionDispatchInfo.Throw()
   at System.Runtime.CompilerServices.TaskAwaiter.ThrowForNonSuccess(Task task)
   at System.Runtime.CompilerServices.TaskAwaiter.HandleNonSuccessAndDebuggerNotification(Task task)
   at Amazon.S3.Internal.AmazonS3ResponseHandler.<InvokeAsync>d__1`1.MoveNext()
--- End of stack trace from previous location where exception was thrown ---
   at System.Runtime.ExceptionServices.ExceptionDispatchInfo.Throw()
   at System.Runtime.CompilerServices.TaskAwaiter.ThrowForNonSuccess(Task task)
   at System.Runtime.CompilerServices.TaskAwaiter.HandleNonSuccessAndDebuggerNotification(Task task)
   at Amazon.Runtime.Internal.ErrorHandler.<InvokeAsync>d__5`1.MoveNext()
--- End of stack trace from previous location where exception was thrown ---
   at System.Runtime.ExceptionServices.ExceptionDispatchInfo.Throw()
   at System.Runtime.CompilerServices.TaskAwaiter.ThrowForNonSuccess(Task task)
   at System.Runtime.CompilerServices.TaskAwaiter.HandleNonSuccessAndDebuggerNotification(Task task)
   at Amazon.Runtime.Internal.CallbackHandler.<InvokeAsync>d__9`1.MoveNext()
--- End of stack trace from previous location where exception was thrown ---
   at System.Runtime.ExceptionServices.ExceptionDispatchInfo.Throw()
   at System.Runtime.CompilerServices.TaskAwaiter.ThrowForNonSuccess(Task task)
   at System.Runtime.CompilerServices.TaskAwaiter.HandleNonSuccessAndDebuggerNotification(Task task)
   at Amazon.Runtime.Internal.CredentialsRetriever.<InvokeAsync>d__7`1.MoveNext()
--- End of stack trace from previous location where exception was thrown ---
   at System.Runtime.ExceptionServices.ExceptionDispatchInfo.Throw()
   at System.Runtime.CompilerServices.TaskAwaiter.ThrowForNonSuccess(Task task)
   at System.Runtime.CompilerServices.TaskAwaiter.HandleNonSuccessAndDebuggerNotification(Task task)
   at Amazon.Runtime.Internal.RetryHandler.<InvokeAsync>d__10`1.MoveNext()
--- End of stack trace from previous location where exception was thrown ---
   at System.Runtime.ExceptionServices.ExceptionDispatchInfo.Throw()
   at Amazon.Runtime.Internal.RetryHandler.<InvokeAsync>d__10`1.MoveNext()
--- End of stack trace from previous location where exception was thrown ---
   at System.Runtime.ExceptionServices.ExceptionDispatchInfo.Throw()
   at System.Runtime.CompilerServices.TaskAwaiter.ThrowForNonSuccess(Task task)
   at System.Runtime.CompilerServices.TaskAwaiter.HandleNonSuccessAndDebuggerNotification(Task task)
   at Amazon.Runtime.Internal.CallbackHandler.<InvokeAsync>d__9`1.MoveNext()
--- End of stack trace from previous location where exception was thrown ---
   at System.Runtime.ExceptionServices.ExceptionDispatchInfo.Throw()
   at System.Runtime.CompilerServices.TaskAwaiter.ThrowForNonSuccess(Task task)
   at System.Runtime.CompilerServices.TaskAwaiter.HandleNonSuccessAndDebuggerNotification(Task task)
   at Amazon.Runtime.Internal.CallbackHandler.<InvokeAsync>d__9`1.MoveNext()
--- End of stack trace from previous location where exception was thrown ---
   at System.Runtime.ExceptionServices.ExceptionDispatchInfo.Throw()
   at System.Runtime.CompilerServices.TaskAwaiter.ThrowForNonSuccess(Task task)
   at System.Runtime.CompilerServices.TaskAwaiter.HandleNonSuccessAndDebuggerNotification(Task task)
   at Amazon.S3.Internal.AmazonS3ExceptionHandler.<InvokeAsync>d__1`1.MoveNext()
--- End of stack trace from previous location where exception was thrown ---
   at System.Runtime.ExceptionServices.ExceptionDispatchInfo.Throw()
   at System.Runtime.CompilerServices.TaskAwaiter.ThrowForNonSuccess(Task task)
   at System.Runtime.CompilerServices.TaskAwaiter.HandleNonSuccessAndDebuggerNotification(Task task)
   at Amazon.Runtime.Internal.ErrorCallbackHandler.<InvokeAsync>d__5`1.MoveNext()
--- End of stack trace from previous location where exception was thrown ---
   at System.Runtime.ExceptionServices.ExceptionDispatchInfo.Throw()
   at System.Runtime.CompilerServices.TaskAwaiter.ThrowForNonSuccess(Task task)
   at System.Runtime.CompilerServices.TaskAwaiter.HandleNonSuccessAndDebuggerNotification(Task task)
   at Amazon.Runtime.Internal.MetricsHandler.<InvokeAsync>d__1`1.MoveNext()
--- End of stack trace from previous location where exception was thrown ---
   at System.Runtime.ExceptionServices.ExceptionDispatchInfo.Throw()
   at System.Runtime.CompilerServices.TaskAwaiter.ThrowForNonSuccess(Task task)
   at System.Runtime.CompilerServices.TaskAwaiter.HandleNonSuccessAndDebuggerNotification(Task task)
   at CKSource.FileSystem.Amazon.AmazonStorage.<FolderExistsAsync>d__18.MoveNext()
--- End of stack trace from previous location where exception was thrown ---
   at System.Runtime.ExceptionServices.ExceptionDispatchInfo.Throw()
   at System.Runtime.CompilerServices.TaskAwaiter.ThrowForNonSuccess(Task task)
   at System.Runtime.CompilerServices.TaskAwaiter.HandleNonSuccessAndDebuggerNotification(Task task)
   at CKSource.CKFinder.Connector.Core.Nodes.Folder.<ExistsAsync>d__9.MoveNext()
--- End of stack trace from previous location where exception was thrown ---
   at System.Runtime.ExceptionServices.ExceptionDispatchInfo.Throw()
   at System.Runtime.CompilerServices.TaskAwaiter.ThrowForNonSuccess(Task task)
   at System.Runtime.CompilerServices.TaskAwaiter.HandleNonSuccessAndDebuggerNotification(Task task)
   at CKSource.CKFinder.Connector.Core.Nodes.NodeValidator.<ThrowIfReadDeniedAsync>d__4.MoveNext()
--- End of stack trace from previous location where exception was thrown ---
   at System.Runtime.ExceptionServices.ExceptionDispatchInfo.Throw()
   at System.Runtime.CompilerServices.TaskAwaiter.ThrowForNonSuccess(Task task)
   at System.Runtime.CompilerServices.TaskAwaiter.HandleNonSuccessAndDebuggerNotification(Task task)
   at CKSource.CKFinder.Connector.Core.Nodes.NodeValidator.<ThrowIfReadDeniedAsync>d__3.MoveNext()
--- End of stack trace from previous location where exception was thrown ---
   at System.Runtime.ExceptionServices.ExceptionDispatchInfo.Throw()
   at System.Runtime.CompilerServices.TaskAwaiter.ThrowForNonSuccess(Task task)
   at System.Runtime.CompilerServices.TaskAwaiter.HandleNonSuccessAndDebuggerNotification(Task task)
   at CKSource.CKFinder.Connector.Core.Commands.Thumbnail.ThumbnailCommandImpl.<ExecuteAsync>d__10.MoveNext()
--- End of stack trace from previous location where exception was thrown ---
   at System.Runtime.ExceptionServices.ExceptionDispatchInfo.Throw()
   at System.Runtime.CompilerServices.TaskAwaiter.ThrowForNonSuccess(Task task)
   at System.Runtime.CompilerServices.TaskAwaiter.HandleNonSuccessAndDebuggerNotification(Task task)
   at CKSource.CKFinder.Connector.Core.CommandHandler.<ExecuteAsync>d__12.MoveNext()    at Amazon.Runtime.Internal.HttpRequest.<GetResponseAsync>d__16.MoveNext()
--- End of stack trace from previous location where exception was thrown ---
   at System.Runtime.ExceptionServices.ExceptionDispatchInfo.Throw()
   at System.Runtime.CompilerServices.TaskAwaiter.ThrowForNonSuccess(Task task)
   at System.Runtime.CompilerServices.TaskAwaiter.HandleNonSuccessAndDebuggerNotification(Task task)
   at Amazon.Runtime.Internal.HttpHandler`1.<InvokeAsync>d__9`1.MoveNext()
--- End of stack trace from previous location where exception was thrown ---
   at System.Runtime.ExceptionServices.ExceptionDispatchInfo.Throw()
   at System.Runtime.CompilerServices.TaskAwaiter.ThrowForNonSuccess(Task task)
   at System.Runtime.CompilerServices.TaskAwaiter.HandleNonSuccessAndDebuggerNotification(Task task)
   at Amazon.Runtime.Internal.RedirectHandler.<InvokeAsync>d__1`1.MoveNext()
--- End of stack trace from previous location where exception was thrown ---
   at System.Runtime.ExceptionServices.ExceptionDispatchInfo.Throw()
   at System.Runtime.CompilerServices.TaskAwaiter.ThrowForNonSuccess(Task task)
   at System.Runtime.CompilerServices.TaskAwaiter.HandleNonSuccessAndDebuggerNotification(Task task)
   at Amazon.Runtime.Internal.Unmarshaller.<InvokeAsync>d__3`1.MoveNext()
--- End of stack trace from previous location where exception was thrown ---
   at System.Runtime.ExceptionServices.ExceptionDispatchInfo.Throw()
   at System.Runtime.CompilerServices.TaskAwaiter.ThrowForNonSuccess(Task task)
   at System.Runtime.CompilerServices.TaskAwaiter.HandleNonSuccessAndDebuggerNotification(Task task)
   at Amazon.S3.Internal.AmazonS3ResponseHandler.<InvokeAsync>d__1`1.MoveNext()
--- End of stack trace from previous location where exception was thrown ---
   at System.Runtime.ExceptionServices.ExceptionDispatchInfo.Throw()
   at System.Runtime.CompilerServices.TaskAwaiter.ThrowForNonSuccess(Task task)
   at System.Runtime.CompilerServices.TaskAwaiter.HandleNonSuccessAndDebuggerNotification(Task task)
   at Amazon.Runtime.Internal.ErrorHandler.<InvokeAsync>d__5`1.MoveNext()
--- End of stack trace from previous location where exception was thrown ---
   at System.Runtime.ExceptionServices.ExceptionDispatchInfo.Throw()
   at System.Runtime.CompilerServices.TaskAwaiter.ThrowForNonSuccess(Task task)
   at System.Runtime.CompilerServices.TaskAwaiter.HandleNonSuccessAndDebuggerNotification(Task task)
   at Amazon.Runtime.Internal.CallbackHandler.<InvokeAsync>d__9`1.MoveNext()
--- End of stack trace from previous location where exception was thrown ---
   at System.Runtime.ExceptionServices.ExceptionDispatchInfo.Throw()
   at System.Runtime.CompilerServices.TaskAwaiter.ThrowForNonSuccess(Task task)
   at System.Runtime.CompilerServices.TaskAwaiter.HandleNonSuccessAndDebuggerNotification(Task task)
   at Amazon.Runtime.Internal.CredentialsRetriever.<InvokeAsync>d__7`1.MoveNext()
--- End of stack trace from previous location where exception was thrown ---
   at System.Runtime.ExceptionServices.ExceptionDispatchInfo.Throw()
   at System.Runtime.CompilerServices.TaskAwaiter.ThrowForNonSuccess(Task task)
   at System.Runtime.CompilerServices.TaskAwaiter.HandleNonSuccessAndDebuggerNotification(Task task)
   at Amazon.Runtime.Internal.RetryHandler.<InvokeAsync>d__10`1.MoveNext()
--- End of stack trace from previous location where exception was thrown ---
   at System.Runtime.ExceptionServices.ExceptionDispatchInfo.Throw()
   at Amazon.Runtime.Internal.RetryHandler.<InvokeAsync>d__10`1.MoveNext()
--- End of stack trace from previous location where exception was thrown ---
   at System.Runtime.ExceptionServices.ExceptionDispatchInfo.Throw()
   at System.Runtime.CompilerServices.TaskAwaiter.ThrowForNonSuccess(Task task)
   at System.Runtime.CompilerServices.TaskAwaiter.HandleNonSuccessAndDebuggerNotification(Task task)
   at Amazon.Runtime.Internal.CallbackHandler.<InvokeAsync>d__9`1.MoveNext()
--- End of stack trace from previous location where exception was thrown ---
   at System.Runtime.ExceptionServices.ExceptionDispatchInfo.Throw()
   at System.Runtime.CompilerServices.TaskAwaiter.ThrowForNonSuccess(Task task)
   at System.Runtime.CompilerServices.TaskAwaiter.HandleNonSuccessAndDebuggerNotification(Task task)
   at Amazon.Runtime.Internal.CallbackHandler.<InvokeAsync>d__9`1.MoveNext()
--- End of stack trace from previous location where exception was thrown ---
   at System.Runtime.ExceptionServices.ExceptionDispatchInfo.Throw()
   at System.Runtime.CompilerServices.TaskAwaiter.ThrowForNonSuccess(Task task)
   at System.Runtime.CompilerServices.TaskAwaiter.HandleNonSuccessAndDebuggerNotification(Task task)
   at Amazon.S3.Internal.AmazonS3ExceptionHandler.<InvokeAsync>d__1`1.MoveNext()
--- End of stack trace from previous location where exception was thrown ---
   at System.Runtime.ExceptionServices.ExceptionDispatchInfo.Throw()
   at System.Runtime.CompilerServices.TaskAwaiter.ThrowForNonSuccess(Task task)
   at System.Runtime.CompilerServices.TaskAwaiter.HandleNonSuccessAndDebuggerNotification(Task task)
   at Amazon.Runtime.Internal.ErrorCallbackHandler.<InvokeAsync>d__5`1.MoveNext()
--- End of stack trace from previous location where exception was thrown ---
   at System.Runtime.ExceptionServices.ExceptionDispatchInfo.Throw()
   at System.Runtime.CompilerServices.TaskAwaiter.ThrowForNonSuccess(Task task)
   at System.Runtime.CompilerServices.TaskAwaiter.HandleNonSuccessAndDebuggerNotification(Task task)
   at Amazon.Runtime.Internal.MetricsHandler.<InvokeAsync>d__1`1.MoveNext()
--- End of stack trace from previous location where exception was thrown ---
   at System.Runtime.ExceptionServices.ExceptionDispatchInfo.Throw()
   at System.Runtime.CompilerServices.TaskAwaiter.ThrowForNonSuccess(Task task)
   at System.Runtime.CompilerServices.TaskAwaiter.HandleNonSuccessAndDebuggerNotification(Task task)
   at CKSource.FileSystem.Amazon.AmazonStorage.<FolderExistsAsync>d__18.MoveNext()
--- End of stack trace from previous location where exception was thrown ---
   at System.Runtime.ExceptionServices.ExceptionDispatchInfo.Throw()
   at System.Runtime.CompilerServices.TaskAwaiter.ThrowForNonSuccess(Task task)
   at System.Runtime.CompilerServices.TaskAwaiter.HandleNonSuccessAndDebuggerNotification(Task task)
   at CKSource.CKFinder.Connector.Core.Nodes.Folder.<ExistsAsync>d__9.MoveNext()
--- End of stack trace from previous location where exception was thrown ---
   at System.Runtime.ExceptionServices.ExceptionDispatchInfo.Throw()
   at System.Runtime.CompilerServices.TaskAwaiter.ThrowForNonSuccess(Task task)
   at System.Runtime.CompilerServices.TaskAwaiter.HandleNonSuccessAndDebuggerNotification(Task task)
   at CKSource.CKFinder.Connector.Core.Nodes.NodeValidator.<ThrowIfReadDeniedAsync>d__4.MoveNext()
--- End of stack trace from previous location where exception was thrown ---
   at System.Runtime.ExceptionServices.ExceptionDispatchInfo.Throw()
   at System.Runtime.CompilerServices.TaskAwaiter.ThrowForNonSuccess(Task task)
   at System.Runtime.CompilerServices.TaskAwaiter.HandleNonSuccessAndDebuggerNotification(Task task)
   at CKSource.CKFinder.Connector.Core.Nodes.NodeValidator.<ThrowIfReadDeniedAsync>d__3.MoveNext()
--- End of stack trace from previous location where exception was thrown ---
   at System.Runtime.ExceptionServices.ExceptionDispatchInfo.Throw()
   at System.Runtime.CompilerServices.TaskAwaiter.ThrowForNonSuccess(Task task)
   at System.Runtime.CompilerServices.TaskAwaiter.HandleNonSuccessAndDebuggerNotification(Task task)
   at CKSource.CKFinder.Connector.Core.Commands.Thumbnail.ThumbnailCommandImpl.<ExecuteAsync>d__10.MoveNext()
--- End of stack trace from previous location where exception was thrown ---
   at System.Runtime.ExceptionServices.ExceptionDispatchInfo.Throw()
   at System.Runtime.CompilerServices.TaskAwaiter.ThrowForNonSuccess(Task task)
   at System.Runtime.CompilerServices.TaskAwaiter.HandleNonSuccessAndDebuggerNotification(Task task)
   at CKSource.CKFinder.Connector.Core.CommandHandler.<ExecuteAsync>d__12.MoveNext()
System.Net.WebException: The request was aborted: The request was canceled.
   at System.Net.HttpWebRequest.BeginGetResponse(AsyncCallback callback, Object state)
   at System.Threading.Tasks.TaskFactory`1.FromAsyncImpl(Func`3 beginMethod, Func`2 endFunction, Action`1 endAction, Object state, TaskCreationOptions creationOptions)
   at System.Net.WebRequest.<GetResponseAsync>b__78_1()
   at System.Threading.Tasks.Task`1.InnerInvoke()
   at System.Threading.Tasks.Task.Execute()
--- End of stack trace from previous location where exception was thrown ---
   at System.Runtime.ExceptionServices.ExceptionDispatchInfo.Throw()
   at System.Runtime.CompilerServices.TaskAwaiter.HandleNonSuccessAndDebuggerNotification(Task task)
   at Amazon.Runtime.Internal.HttpRequest.<GetResponseAsync>d__16.MoveNext()    at System.Net.HttpWebRequest.BeginGetResponse(AsyncCallback callback, Object state)
   at System.Threading.Tasks.TaskFactory`1.FromAsyncImpl(Func`3 beginMethod, Func`2 endFunction, Action`1 endAction, Object state, TaskCreationOptions creationOptions)
   at System.Net.WebRequest.<GetResponseAsync>b__78_1()
   at System.Threading.Tasks.Task`1.InnerInvoke()
   at System.Threading.Tasks.Task.Execute()
--- End of stack trace from previous location where exception was thrown ---
   at System.Runtime.ExceptionServices.ExceptionDispatchInfo.Throw()
   at System.Runtime.CompilerServices.TaskAwaiter.HandleNonSuccessAndDebuggerNotification(Task task)
   at Amazon.Runtime.Internal.HttpRequest.<GetResponseAsync>d__16.MoveNext()
Fatal | CKSource.CKFinder.Connector.Core.CommandHandler | 2019-03-04 10:17:55.4792 | An unknown error has occured during execution of Thumbnail command.| System.OperationCanceledException: The request was aborted: The request was canceled. ---> System.Net.WebException: The request was aborted: The request was canceled.
   at System.Net.HttpWebRequest.BeginGetResponse(AsyncCallback callback, Object state)
   at System.Threading.Tasks.TaskFactory`1.FromAsyncImpl(Func`3 beginMethod, Func`2 endFunction, Action`1 endAction, Object state, TaskCreationOptions creationOptions)
   at System.Net.WebRequest.<GetResponseAsync>b__78_1()
   at System.Threading.Tasks.Task`1.InnerInvoke()
   at System.Threading.Tasks.Task.Execute()
--- End of stack trace from previous location where exception was thrown ---
   at System.Runtime.ExceptionServices.ExceptionDispatchInfo.Throw()
   at System.Runtime.CompilerServices.TaskAwaiter.HandleNonSuccessAndDebuggerNotification(Task task)
   at Amazon.Runtime.Internal.HttpRequest.<GetResponseAsync>d__16.MoveNext()
   --- End of inner exception stack trace ---
   at Amazon.Runtime.Internal.HttpRequest.<GetResponseAsync>d__16.MoveNext()
--- End of stack trace from previous location where exception was thrown ---
   at System.Runtime.ExceptionServices.ExceptionDispatchInfo.Throw()
   at System.Runtime.CompilerServices.TaskAwaiter.ThrowForNonSuccess(Task task)
   at System.Runtime.CompilerServices.TaskAwaiter.HandleNonSuccessAndDebuggerNotification(Task task)
   at Amazon.Runtime.Internal.HttpHandler`1.<InvokeAsync>d__9`1.MoveNext()
--- End of stack trace from previous location where exception was thrown ---
   at System.Runtime.ExceptionServices.ExceptionDispatchInfo.Throw()
   at System.Runtime.CompilerServices.TaskAwaiter.ThrowForNonSuccess(Task task)
   at System.Runtime.CompilerServices.TaskAwaiter.HandleNonSuccessAndDebuggerNotification(Task task)
   at Amazon.Runtime.Internal.RedirectHandler.<InvokeAsync>d__1`1.MoveNext()
--- End of stack trace from previous location where exception was thrown ---
   at System.Runtime.ExceptionServices.ExceptionDispatchInfo.Throw()
   at System.Runtime.CompilerServices.TaskAwaiter.ThrowForNonSuccess(Task task)
   at System.Runtime.CompilerServices.TaskAwaiter.HandleNonSuccessAndDebuggerNotification(Task task)
   at Amazon.Runtime.Internal.Unmarshaller.<InvokeAsync>d__3`1.MoveNext()
--- End of stack trace from previous location where exception was thrown ---
   at System.Runtime.ExceptionServices.ExceptionDispatchInfo.Throw()
   at System.Runtime.CompilerServices.TaskAwaiter.ThrowForNonSuccess(Task task)
   at System.Runtime.CompilerServices.TaskAwaiter.HandleNonSuccessAndDebuggerNotification(Task task)
   at Amazon.S3.Internal.AmazonS3ResponseHandler.<InvokeAsync>d__1`1.MoveNext()
--- End of stack trace from previous location where exception was thrown ---
   at System.Runtime.ExceptionServices.ExceptionDispatchInfo.Throw()
   at System.Runtime.CompilerServices.TaskAwaiter.ThrowForNonSuccess(Task task)
   at System.Runtime.CompilerServices.TaskAwaiter.HandleNonSuccessAndDebuggerNotification(Task task)
   at Amazon.Runtime.Internal.ErrorHandler.<InvokeAsync>d__5`1.MoveNext()
--- End of stack trace from previous location where exception was thrown ---
   at System.Runtime.ExceptionServices.ExceptionDispatchInfo.Throw()
   at System.Runtime.CompilerServices.TaskAwaiter.ThrowForNonSuccess(Task task)
   at System.Runtime.CompilerServices.TaskAwaiter.HandleNonSuccessAndDebuggerNotification(Task task)
   at Amazon.Runtime.Internal.CallbackHandler.<InvokeAsync>d__9`1.MoveNext()
--- End of stack trace from previous location where exception was thrown ---
   at System.Runtime.ExceptionServices.ExceptionDispatchInfo.Throw()
   at System.Runtime.CompilerServices.TaskAwaiter.ThrowForNonSuccess(Task task)
   at System.Runtime.CompilerServices.TaskAwaiter.HandleNonSuccessAndDebuggerNotification(Task task)
   at Amazon.Runtime.Internal.CredentialsRetriever.<InvokeAsync>d__7`1.MoveNext()
--- End of stack trace from previous location where exception was thrown ---
   at System.Runtime.ExceptionServices.ExceptionDispatchInfo.Throw()
   at System.Runtime.CompilerServices.TaskAwaiter.ThrowForNonSuccess(Task task)
   at System.Runtime.CompilerServices.TaskAwaiter.HandleNonSuccessAndDebuggerNotification(Task task)
   at Amazon.Runtime.Internal.RetryHandler.<InvokeAsync>d__10`1.MoveNext()
--- End of stack trace from previous location where exception was thrown ---
   at System.Runtime.ExceptionServices.ExceptionDispatchInfo.Throw()
   at Amazon.Runtime.Internal.RetryHandler.<InvokeAsync>d__10`1.MoveNext()
--- End of stack trace from previous location where exception was thrown ---
   at System.Runtime.ExceptionServices.ExceptionDispatchInfo.Throw()
   at System.Runtime.CompilerServices.TaskAwaiter.ThrowForNonSuccess(Task task)
   at System.Runtime.CompilerServices.TaskAwaiter.HandleNonSuccessAndDebuggerNotification(Task task)
   at Amazon.Runtime.Internal.CallbackHandler.<InvokeAsync>d__9`1.MoveNext()
--- End of stack trace from previous location where exception was thrown ---
   at System.Runtime.ExceptionServices.ExceptionDispatchInfo.Throw()
   at System.Runtime.CompilerServices.TaskAwaiter.ThrowForNonSuccess(Task task)
   at System.Runtime.CompilerServices.TaskAwaiter.HandleNonSuccessAndDebuggerNotification(Task task)
   at Amazon.Runtime.Internal.CallbackHandler.<InvokeAsync>d__9`1.MoveNext()
--- End of stack trace from previous location where exception was thrown ---
   at System.Runtime.ExceptionServices.ExceptionDispatchInfo.Throw()
   at System.Runtime.CompilerServices.TaskAwaiter.ThrowForNonSuccess(Task task)
   at System.Runtime.CompilerServices.TaskAwaiter.HandleNonSuccessAndDebuggerNotification(Task task)
   at Amazon.S3.Internal.AmazonS3ExceptionHandler.<InvokeAsync>d__1`1.MoveNext()
--- End of stack trace from previous location where exception was thrown ---
   at System.Runtime.ExceptionServices.ExceptionDispatchInfo.Throw()
   at System.Runtime.CompilerServices.TaskAwaiter.ThrowForNonSuccess(Task task)
   at System.Runtime.CompilerServices.TaskAwaiter.HandleNonSuccessAndDebuggerNotification(Task task)
   at Amazon.Runtime.Internal.ErrorCallbackHandler.<InvokeAsync>d__5`1.MoveNext()
--- End of stack trace from previous location where exception was thrown ---
   at System.Runtime.ExceptionServices.ExceptionDispatchInfo.Throw()
   at System.Runtime.CompilerServices.TaskAwaiter.ThrowForNonSuccess(Task task)
   at System.Runtime.CompilerServices.TaskAwaiter.HandleNonSuccessAndDebuggerNotification(Task task)
   at Amazon.Runtime.Internal.MetricsHandler.<InvokeAsync>d__1`1.MoveNext()
--- End of stack trace from previous location where exception was thrown ---
   at System.Runtime.ExceptionServices.ExceptionDispatchInfo.Throw()
   at System.Runtime.CompilerServices.TaskAwaiter.ThrowForNonSuccess(Task task)
   at System.Runtime.CompilerServices.TaskAwaiter.HandleNonSuccessAndDebuggerNotification(Task task)
   at CKSource.FileSystem.Amazon.AmazonStorage.<FolderExistsAsync>d__18.MoveNext()
--- End of stack trace from previous location where exception was thrown ---
   at System.Runtime.ExceptionServices.ExceptionDispatchInfo.Throw()
   at System.Runtime.CompilerServices.TaskAwaiter.ThrowForNonSuccess(Task task)
   at System.Runtime.CompilerServices.TaskAwaiter.HandleNonSuccessAndDebuggerNotification(Task task)
   at CKSource.CKFinder.Connector.Core.Nodes.Folder.<ExistsAsync>d__9.MoveNext()
--- End of stack trace from previous location where exception was thrown ---
   at System.Runtime.ExceptionServices.ExceptionDispatchInfo.Throw()
   at System.Runtime.CompilerServices.TaskAwaiter.ThrowForNonSuccess(Task task)
   at System.Runtime.CompilerServices.TaskAwaiter.HandleNonSuccessAndDebuggerNotification(Task task)
   at CKSource.CKFinder.Connector.Core.Nodes.NodeValidator.<ThrowIfReadDeniedAsync>d__4.MoveNext()
--- End of stack trace from previous location where exception was thrown ---
   at System.Runtime.ExceptionServices.ExceptionDispatchInfo.Throw()
   at System.Runtime.CompilerServices.TaskAwaiter.ThrowForNonSuccess(Task task)
   at System.Runtime.CompilerServices.TaskAwaiter.HandleNonSuccessAndDebuggerNotification(Task task)
   at CKSource.CKFinder.Connector.Core.Nodes.NodeValidator.<ThrowIfReadDeniedAsync>d__3.MoveNext()
--- End of stack trace from previous location where exception was thrown ---
   at System.Runtime.ExceptionServices.ExceptionDispatchInfo.Throw()
   at System.Runtime.CompilerServices.TaskAwaiter.ThrowForNonSuccess(Task task)
   at System.Runtime.CompilerServices.TaskAwaiter.HandleNonSuccessAndDebuggerNotification(Task task)
   at CKSource.CKFinder.Connector.Core.Commands.Thumbnail.ThumbnailCommandImpl.<ExecuteAsync>d__10.MoveNext()
--- End of stack trace from previous location where exception was thrown ---
   at System.Runtime.ExceptionServices.ExceptionDispatchInfo.Throw()
   at System.Runtime.CompilerServices.TaskAwaiter.ThrowForNonSuccess(Task task)
   at System.Runtime.CompilerServices.TaskAwaiter.HandleNonSuccessAndDebuggerNotification(Task task)
   at CKSource.CKFinder.Connector.Core.CommandHandler.<ExecuteAsync>d__12.MoveNext()    at Amazon.Runtime.Internal.HttpRequest.<GetResponseAsync>d__16.MoveNext()
--- End of stack trace from previous location where exception was thrown ---
   at System.Runtime.ExceptionServices.ExceptionDispatchInfo.Throw()
   at System.Runtime.CompilerServices.TaskAwaiter.ThrowForNonSuccess(Task task)
   at System.Runtime.CompilerServices.TaskAwaiter.HandleNonSuccessAndDebuggerNotification(Task task)
   at Amazon.Runtime.Internal.HttpHandler`1.<InvokeAsync>d__9`1.MoveNext()
--- End of stack trace from previous location where exception was thrown ---
   at System.Runtime.ExceptionServices.ExceptionDispatchInfo.Throw()
   at System.Runtime.CompilerServices.TaskAwaiter.ThrowForNonSuccess(Task task)
   at System.Runtime.CompilerServices.TaskAwaiter.HandleNonSuccessAndDebuggerNotification(Task task)
   at Amazon.Runtime.Internal.RedirectHandler.<InvokeAsync>d__1`1.MoveNext()
--- End of stack trace from previous location where exception was thrown ---
   at System.Runtime.ExceptionServices.ExceptionDispatchInfo.Throw()
   at System.Runtime.CompilerServices.TaskAwaiter.ThrowForNonSuccess(Task task)
   at System.Runtime.CompilerServices.TaskAwaiter.HandleNonSuccessAndDebuggerNotification(Task task)
   at Amazon.Runtime.Internal.Unmarshaller.<InvokeAsync>d__3`1.MoveNext()
--- End of stack trace from previous location where exception was thrown ---
   at System.Runtime.ExceptionServices.ExceptionDispatchInfo.Throw()
   at System.Runtime.CompilerServices.TaskAwaiter.ThrowForNonSuccess(Task task)
   at System.Runtime.CompilerServices.TaskAwaiter.HandleNonSuccessAndDebuggerNotification(Task task)
   at Amazon.S3.Internal.AmazonS3ResponseHandler.<InvokeAsync>d__1`1.MoveNext()
--- End of stack trace from previous location where exception was thrown ---
   at System.Runtime.ExceptionServices.ExceptionDispatchInfo.Throw()
   at System.Runtime.CompilerServices.TaskAwaiter.ThrowForNonSuccess(Task task)
   at System.Runtime.CompilerServices.TaskAwaiter.HandleNonSuccessAndDebuggerNotification(Task task)
   at Amazon.Runtime.Internal.ErrorHandler.<InvokeAsync>d__5`1.MoveNext()
--- End of stack trace from previous location where exception was thrown ---
   at System.Runtime.ExceptionServices.ExceptionDispatchInfo.Throw()
   at System.Runtime.CompilerServices.TaskAwaiter.ThrowForNonSuccess(Task task)
   at System.Runtime.CompilerServices.TaskAwaiter.HandleNonSuccessAndDebuggerNotification(Task task)
   at Amazon.Runtime.Internal.CallbackHandler.<InvokeAsync>d__9`1.MoveNext()
--- End of stack trace from previous location where exception was thrown ---
   at System.Runtime.ExceptionServices.ExceptionDispatchInfo.Throw()
   at System.Runtime.CompilerServices.TaskAwaiter.ThrowForNonSuccess(Task task)
   at System.Runtime.CompilerServices.TaskAwaiter.HandleNonSuccessAndDebuggerNotification(Task task)
   at Amazon.Runtime.Internal.CredentialsRetriever.<InvokeAsync>d__7`1.MoveNext()
--- End of stack trace from previous location where exception was thrown ---
   at System.Runtime.ExceptionServices.ExceptionDispatchInfo.Throw()
   at System.Runtime.CompilerServices.TaskAwaiter.ThrowForNonSuccess(Task task)
   at System.Runtime.CompilerServices.TaskAwaiter.HandleNonSuccessAndDebuggerNotification(Task task)
   at Amazon.Runtime.Internal.RetryHandler.<InvokeAsync>d__10`1.MoveNext()
--- End of stack trace from previous location where exception was thrown ---
   at System.Runtime.ExceptionServices.ExceptionDispatchInfo.Throw()
   at Amazon.Runtime.Internal.RetryHandler.<InvokeAsync>d__10`1.MoveNext()
--- End of stack trace from previous location where exception was thrown ---
   at System.Runtime.ExceptionServices.ExceptionDispatchInfo.Throw()
   at System.Runtime.CompilerServices.TaskAwaiter.ThrowForNonSuccess(Task task)
   at System.Runtime.CompilerServices.TaskAwaiter.HandleNonSuccessAndDebuggerNotification(Task task)
   at Amazon.Runtime.Internal.CallbackHandler.<InvokeAsync>d__9`1.MoveNext()
--- End of stack trace from previous location where exception was thrown ---
   at System.Runtime.ExceptionServices.ExceptionDispatchInfo.Throw()
   at System.Runtime.CompilerServices.TaskAwaiter.ThrowForNonSuccess(Task task)
   at System.Runtime.CompilerServices.TaskAwaiter.HandleNonSuccessAndDebuggerNotification(Task task)
   at Amazon.Runtime.Internal.CallbackHandler.<InvokeAsync>d__9`1.MoveNext()
--- End of stack trace from previous location where exception was thrown ---
   at System.Runtime.ExceptionServices.ExceptionDispatchInfo.Throw()
   at System.Runtime.CompilerServices.TaskAwaiter.ThrowForNonSuccess(Task task)
   at System.Runtime.CompilerServices.TaskAwaiter.HandleNonSuccessAndDebuggerNotification(Task task)
   at Amazon.S3.Internal.AmazonS3ExceptionHandler.<InvokeAsync>d__1`1.MoveNext()
--- End of stack trace from previous location where exception was thrown ---
   at System.Runtime.ExceptionServices.ExceptionDispatchInfo.Throw()
   at System.Runtime.CompilerServices.TaskAwaiter.ThrowForNonSuccess(Task task)
   at System.Runtime.CompilerServices.TaskAwaiter.HandleNonSuccessAndDebuggerNotification(Task task)
   at Amazon.Runtime.Internal.ErrorCallbackHandler.<InvokeAsync>d__5`1.MoveNext()
--- End of stack trace from previous location where exception was thrown ---
   at System.Runtime.ExceptionServices.ExceptionDispatchInfo.Throw()
   at System.Runtime.CompilerServices.TaskAwaiter.ThrowForNonSuccess(Task task)
   at System.Runtime.CompilerServices.TaskAwaiter.HandleNonSuccessAndDebuggerNotification(Task task)
   at Amazon.Runtime.Internal.MetricsHandler.<InvokeAsync>d__1`1.MoveNext()
--- End of stack trace from previous location where exception was thrown ---
   at System.Runtime.ExceptionServices.ExceptionDispatchInfo.Throw()
   at System.Runtime.CompilerServices.TaskAwaiter.ThrowForNonSuccess(Task task)
   at System.Runtime.CompilerServices.TaskAwaiter.HandleNonSuccessAndDebuggerNotification(Task task)
   at CKSource.FileSystem.Amazon.AmazonStorage.<FolderExistsAsync>d__18.MoveNext()
--- End of stack trace from previous location where exception was thrown ---
   at System.Runtime.ExceptionServices.ExceptionDispatchInfo.Throw()
   at System.Runtime.CompilerServices.TaskAwaiter.ThrowForNonSuccess(Task task)
   at System.Runtime.CompilerServices.TaskAwaiter.HandleNonSuccessAndDebuggerNotification(Task task)
   at CKSource.CKFinder.Connector.Core.Nodes.Folder.<ExistsAsync>d__9.MoveNext()
--- End of stack trace from previous location where exception was thrown ---
   at System.Runtime.ExceptionServices.ExceptionDispatchInfo.Throw()
   at System.Runtime.CompilerServices.TaskAwaiter.ThrowForNonSuccess(Task task)
   at System.Runtime.CompilerServices.TaskAwaiter.HandleNonSuccessAndDebuggerNotification(Task task)
   at CKSource.CKFinder.Connector.Core.Nodes.NodeValidator.<ThrowIfReadDeniedAsync>d__4.MoveNext()
--- End of stack trace from previous location where exception was thrown ---
   at System.Runtime.ExceptionServices.ExceptionDispatchInfo.Throw()
   at System.Runtime.CompilerServices.TaskAwaiter.ThrowForNonSuccess(Task task)
   at System.Runtime.CompilerServices.TaskAwaiter.HandleNonSuccessAndDebuggerNotification(Task task)
   at CKSource.CKFinder.Connector.Core.Nodes.NodeValidator.<ThrowIfReadDeniedAsync>d__3.MoveNext()
--- End of stack trace from previous location where exception was thrown ---
   at System.Runtime.ExceptionServices.ExceptionDispatchInfo.Throw()
   at System.Runtime.CompilerServices.TaskAwaiter.ThrowForNonSuccess(Task task)
   at System.Runtime.CompilerServices.TaskAwaiter.HandleNonSuccessAndDebuggerNotification(Task task)
   at CKSource.CKFinder.Connector.Core.Commands.Thumbnail.ThumbnailCommandImpl.<ExecuteAsync>d__10.MoveNext()
--- End of stack trace from previous location where exception was thrown ---
   at System.Runtime.ExceptionServices.ExceptionDispatchInfo.Throw()
   at System.Runtime.CompilerServices.TaskAwaiter.ThrowForNonSuccess(Task task)
   at System.Runtime.CompilerServices.TaskAwaiter.HandleNonSuccessAndDebuggerNotification(Task task)
   at CKSource.CKFinder.Connector.Core.CommandHandler.<ExecuteAsync>d__12.MoveNext()
System.Net.WebException: The request was aborted: The request was canceled.
   at System.Net.HttpWebRequest.BeginGetResponse(AsyncCallback callback, Object state)
   at System.Threading.Tasks.TaskFactory`1.FromAsyncImpl(Func`3 beginMethod, Func`2 endFunction, Action`1 endAction, Object state, TaskCreationOptions creationOptions)
   at System.Net.WebRequest.<GetResponseAsync>b__78_1()
   at System.Threading.Tasks.Task`1.InnerInvoke()
   at System.Threading.Tasks.Task.Execute()
--- End of stack trace from previous location where exception was thrown ---
   at System.Runtime.ExceptionServices.ExceptionDispatchInfo.Throw()
   at System.Runtime.CompilerServices.TaskAwaiter.HandleNonSuccessAndDebuggerNotification(Task task)
   at Amazon.Runtime.Internal.HttpRequest.<GetResponseAsync>d__16.MoveNext()    at System.Net.HttpWebRequest.BeginGetResponse(AsyncCallback callback, Object state)
   at System.Threading.Tasks.TaskFactory`1.FromAsyncImpl(Func`3 beginMethod, Func`2 endFunction, Action`1 endAction, Object state, TaskCreationOptions creationOptions)
   at System.Net.WebRequest.<GetResponseAsync>b__78_1()
   at System.Threading.Tasks.Task`1.InnerInvoke()
   at System.Threading.Tasks.Task.Execute()
--- End of stack trace from previous location where exception was thrown ---
   at System.Runtime.ExceptionServices.ExceptionDispatchInfo.Throw()
   at System.Runtime.CompilerServices.TaskAwaiter.HandleNonSuccessAndDebuggerNotification(Task task)
   at Amazon.Runtime.Internal.HttpRequest.<GetResponseAsync>d__16.MoveNext()
Fatal | CKSource.CKFinder.Connector.Core.CommandHandler | 2019-03-07 11:29:24.0847 | An unknown error has occured during execution of GetFiles command.| System.OperationCanceledException: The request was aborted: The request was canceled. ---> System.Net.WebException: The request was aborted: The request was canceled.
   at System.Net.HttpWebRequest.BeginGetResponse(AsyncCallback callback, Object state)
   at System.Threading.Tasks.TaskFactory`1.FromAsyncImpl(Func`3 beginMethod, Func`2 endFunction, Action`1 endAction, Object state, TaskCreationOptions creationOptions)
   at System.Net.WebRequest.<GetResponseAsync>b__78_1()
   at System.Threading.Tasks.Task`1.InnerInvoke()
   at System.Threading.Tasks.Task.Execute()
--- End of stack trace from previous location where exception was thrown ---
   at System.Runtime.ExceptionServices.ExceptionDispatchInfo.Throw()
   at System.Runtime.CompilerServices.TaskAwaiter.HandleNonSuccessAndDebuggerNotification(Task task)
   at Amazon.Runtime.Internal.HttpRequest.<GetResponseAsync>d__16.MoveNext()
   --- End of inner exception stack trace ---
   at Amazon.Runtime.Internal.HttpRequest.<GetResponseAsync>d__16.MoveNext()
--- End of stack trace from previous location where exception was thrown ---
   at System.Runtime.ExceptionServices.ExceptionDispatchInfo.Throw()
   at System.Runtime.CompilerServices.TaskAwaiter.ThrowForNonSuccess(Task task)
   at System.Runtime.CompilerServices.TaskAwaiter.HandleNonSuccessAndDebuggerNotification(Task task)
   at Amazon.Runtime.Internal.HttpHandler`1.<InvokeAsync>d__9`1.MoveNext()
--- End of stack trace from previous location where exception was thrown ---
   at System.Runtime.ExceptionServices.ExceptionDispatchInfo.Throw()
   at System.Runtime.CompilerServices.TaskAwaiter.ThrowForNonSuccess(Task task)
   at System.Runtime.CompilerServices.TaskAwaiter.HandleNonSuccessAndDebuggerNotification(Task task)
   at Amazon.Runtime.Internal.RedirectHandler.<InvokeAsync>d__1`1.MoveNext()
--- End of stack trace from previous location where exception was thrown ---
   at System.Runtime.ExceptionServices.ExceptionDispatchInfo.Throw()
   at System.Runtime.CompilerServices.TaskAwaiter.ThrowForNonSuccess(Task task)
   at System.Runtime.CompilerServices.TaskAwaiter.HandleNonSuccessAndDebuggerNotification(Task task)
   at Amazon.Runtime.Internal.Unmarshaller.<InvokeAsync>d__3`1.MoveNext()
--- End of stack trace from previous location where exception was thrown ---
   at System.Runtime.ExceptionServices.ExceptionDispatchInfo.Throw()
   at System.Runtime.CompilerServices.TaskAwaiter.ThrowForNonSuccess(Task task)
   at System.Runtime.CompilerServices.TaskAwaiter.HandleNonSuccessAndDebuggerNotification(Task task)
   at Amazon.S3.Internal.AmazonS3ResponseHandler.<InvokeAsync>d__1`1.MoveNext()
--- End of stack trace from previous location where exception was thrown ---
   at System.Runtime.ExceptionServices.ExceptionDispatchInfo.Throw()
   at System.Runtime.CompilerServices.TaskAwaiter.ThrowForNonSuccess(Task task)
   at System.Runtime.CompilerServices.TaskAwaiter.HandleNonSuccessAndDebuggerNotification(Task task)
   at Amazon.Runtime.Internal.ErrorHandler.<InvokeAsync>d__5`1.MoveNext()
--- End of stack trace from previous location where exception was thrown ---
   at System.Runtime.ExceptionServices.ExceptionDispatchInfo.Throw()
   at System.Runtime.CompilerServices.TaskAwaiter.ThrowForNonSuccess(Task task)
   at System.Runtime.CompilerServices.TaskAwaiter.HandleNonSuccessAndDebuggerNotification(Task task)
   at Amazon.Runtime.Internal.CallbackHandler.<InvokeAsync>d__9`1.MoveNext()
--- End of stack trace from previous location where exception was thrown ---
   at System.Runtime.ExceptionServices.ExceptionDispatchInfo.Throw()
   at System.Runtime.CompilerServices.TaskAwaiter.ThrowForNonSuccess(Task task)
   at System.Runtime.CompilerServices.TaskAwaiter.HandleNonSuccessAndDebuggerNotification(Task task)
   at Amazon.Runtime.Internal.CredentialsRetriever.<InvokeAsync>d__7`1.MoveNext()
--- End of stack trace from previous location where exception was thrown ---
   at System.Runtime.ExceptionServices.ExceptionDispatchInfo.Throw()
   at System.Runtime.CompilerServices.TaskAwaiter.ThrowForNonSuccess(Task task)
   at System.Runtime.CompilerServices.TaskAwaiter.HandleNonSuccessAndDebuggerNotification(Task task)
   at Amazon.Runtime.Internal.RetryHandler.<InvokeAsync>d__10`1.MoveNext()
--- End of stack trace from previous location where exception was thrown ---
   at System.Runtime.ExceptionServices.ExceptionDispatchInfo.Throw()
   at Amazon.Runtime.Internal.RetryHandler.<InvokeAsync>d__10`1.MoveNext()
--- End of stack trace from previous location where exception was thrown ---
   at System.Runtime.ExceptionServices.ExceptionDispatchInfo.Throw()
   at System.Runtime.CompilerServices.TaskAwaiter.ThrowForNonSuccess(Task task)
   at System.Runtime.CompilerServices.TaskAwaiter.HandleNonSuccessAndDebuggerNotification(Task task)
   at Amazon.Runtime.Internal.CallbackHandler.<InvokeAsync>d__9`1.MoveNext()
--- End of stack trace from previous location where exception was thrown ---
   at System.Runtime.ExceptionServices.ExceptionDispatchInfo.Throw()
   at System.Runtime.CompilerServices.TaskAwaiter.ThrowForNonSuccess(Task task)
   at System.Runtime.CompilerServices.TaskAwaiter.HandleNonSuccessAndDebuggerNotification(Task task)
   at Amazon.Runtime.Internal.CallbackHandler.<InvokeAsync>d__9`1.MoveNext()
--- End of stack trace from previous location where exception was thrown ---
   at System.Runtime.ExceptionServices.ExceptionDispatchInfo.Throw()
   at System.Runtime.CompilerServices.TaskAwaiter.ThrowForNonSuccess(Task task)
   at System.Runtime.CompilerServices.TaskAwaiter.HandleNonSuccessAndDebuggerNotification(Task task)
   at Amazon.S3.Internal.AmazonS3ExceptionHandler.<InvokeAsync>d__1`1.MoveNext()
--- End of stack trace from previous location where exception was thrown ---
   at System.Runtime.ExceptionServices.ExceptionDispatchInfo.Throw()
   at System.Runtime.CompilerServices.TaskAwaiter.ThrowForNonSuccess(Task task)
   at System.Runtime.CompilerServices.TaskAwaiter.HandleNonSuccessAndDebuggerNotification(Task task)
   at Amazon.Runtime.Internal.ErrorCallbackHandler.<InvokeAsync>d__5`1.MoveNext()
--- End of stack trace from previous location where exception was thrown ---
   at System.Runtime.ExceptionServices.ExceptionDispatchInfo.Throw()
   at System.Runtime.CompilerServices.TaskAwaiter.ThrowForNonSuccess(Task task)
   at System.Runtime.CompilerServices.TaskAwaiter.HandleNonSuccessAndDebuggerNotification(Task task)
   at Amazon.Runtime.Internal.MetricsHandler.<InvokeAsync>d__1`1.MoveNext()
--- End of stack trace from previous location where exception was thrown ---
   at System.Runtime.ExceptionServices.ExceptionDispatchInfo.Throw()
   at System.Runtime.CompilerServices.TaskAwaiter.ThrowForNonSuccess(Task task)
   at System.Runtime.CompilerServices.TaskAwaiter.HandleNonSuccessAndDebuggerNotification(Task task)
   at CKSource.FileSystem.Amazon.AmazonStorage.<GetFileInfosInternalAsync>d__29.MoveNext()
--- End of stack trace from previous location where exception was thrown ---
   at System.Runtime.ExceptionServices.ExceptionDispatchInfo.Throw()
   at System.Runtime.CompilerServices.TaskAwaiter.ThrowForNonSuccess(Task task)
   at System.Runtime.CompilerServices.TaskAwaiter.HandleNonSuccessAndDebuggerNotification(Task task)
   at CKSource.CKFinder.Connector.Core.Nodes.Folder.<ListFilesAsync>d__12.MoveNext()
--- End of stack trace from previous location where exception was thrown ---
   at System.Runtime.ExceptionServices.ExceptionDispatchInfo.Throw()
   at System.Runtime.CompilerServices.TaskAwaiter.ThrowForNonSuccess(Task task)
   at System.Runtime.CompilerServices.TaskAwaiter.HandleNonSuccessAndDebuggerNotification(Task task)
   at CKSource.CKFinder.Connector.Core.Commands.GetFiles.GetFilesCommandImpl.<ExecuteAsync>d__5.MoveNext()
--- End of stack trace from previous location where exception was thrown ---
   at System.Runtime.ExceptionServices.ExceptionDispatchInfo.Throw()
   at System.Runtime.CompilerServices.TaskAwaiter.ThrowForNonSuccess(Task task)
   at System.Runtime.CompilerServices.TaskAwaiter.HandleNonSuccessAndDebuggerNotification(Task task)
   at CKSource.CKFinder.Connector.Core.CommandHandler.<ExecuteAsync>d__12.MoveNext()    at Amazon.Runtime.Internal.HttpRequest.<GetResponseAsync>d__16.MoveNext()
--- End of stack trace from previous location where exception was thrown ---
   at System.Runtime.ExceptionServices.ExceptionDispatchInfo.Throw()
   at System.Runtime.CompilerServices.TaskAwaiter.ThrowForNonSuccess(Task task)
   at System.Runtime.CompilerServices.TaskAwaiter.HandleNonSuccessAndDebuggerNotification(Task task)
   at Amazon.Runtime.Internal.HttpHandler`1.<InvokeAsync>d__9`1.MoveNext()
--- End of stack trace from previous location where exception was thrown ---
   at System.Runtime.ExceptionServices.ExceptionDispatchInfo.Throw()
   at System.Runtime.CompilerServices.TaskAwaiter.ThrowForNonSuccess(Task task)
   at System.Runtime.CompilerServices.TaskAwaiter.HandleNonSuccessAndDebuggerNotification(Task task)
   at Amazon.Runtime.Internal.RedirectHandler.<InvokeAsync>d__1`1.MoveNext()
--- End of stack trace from previous location where exception was thrown ---
   at System.Runtime.ExceptionServices.ExceptionDispatchInfo.Throw()
   at System.Runtime.CompilerServices.TaskAwaiter.ThrowForNonSuccess(Task task)
   at System.Runtime.CompilerServices.TaskAwaiter.HandleNonSuccessAndDebuggerNotification(Task task)
   at Amazon.Runtime.Internal.Unmarshaller.<InvokeAsync>d__3`1.MoveNext()
--- End of stack trace from previous location where exception was thrown ---
   at System.Runtime.ExceptionServices.ExceptionDispatchInfo.Throw()
   at System.Runtime.CompilerServices.TaskAwaiter.ThrowForNonSuccess(Task task)
   at System.Runtime.CompilerServices.TaskAwaiter.HandleNonSuccessAndDebuggerNotification(Task task)
   at Amazon.S3.Internal.AmazonS3ResponseHandler.<InvokeAsync>d__1`1.MoveNext()
--- End of stack trace from previous location where exception was thrown ---
   at System.Runtime.ExceptionServices.ExceptionDispatchInfo.Throw()
   at System.Runtime.CompilerServices.TaskAwaiter.ThrowForNonSuccess(Task task)
   at System.Runtime.CompilerServices.TaskAwaiter.HandleNonSuccessAndDebuggerNotification(Task task)
   at Amazon.Runtime.Internal.ErrorHandler.<InvokeAsync>d__5`1.MoveNext()
--- End of stack trace from previous location where exception was thrown ---
   at System.Runtime.ExceptionServices.ExceptionDispatchInfo.Throw()
   at System.Runtime.CompilerServices.TaskAwaiter.ThrowForNonSuccess(Task task)
   at System.Runtime.CompilerServices.TaskAwaiter.HandleNonSuccessAndDebuggerNotification(Task task)
   at Amazon.Runtime.Internal.CallbackHandler.<InvokeAsync>d__9`1.MoveNext()
--- End of stack trace from previous location where exception was thrown ---
   at System.Runtime.ExceptionServices.ExceptionDispatchInfo.Throw()
   at System.Runtime.CompilerServices.TaskAwaiter.ThrowForNonSuccess(Task task)
   at System.Runtime.CompilerServices.TaskAwaiter.HandleNonSuccessAndDebuggerNotification(Task task)
   at Amazon.Runtime.Internal.CredentialsRetriever.<InvokeAsync>d__7`1.MoveNext()
--- End of stack trace from previous location where exception was thrown ---
   at System.Runtime.ExceptionServices.ExceptionDispatchInfo.Throw()
   at System.Runtime.CompilerServices.TaskAwaiter.ThrowForNonSuccess(Task task)
   at System.Runtime.CompilerServices.TaskAwaiter.HandleNonSuccessAndDebuggerNotification(Task task)
   at Amazon.Runtime.Internal.RetryHandler.<InvokeAsync>d__10`1.MoveNext()
--- End of stack trace from previous location where exception was thrown ---
   at System.Runtime.ExceptionServices.ExceptionDispatchInfo.Throw()
   at Amazon.Runtime.Internal.RetryHandler.<InvokeAsync>d__10`1.MoveNext()
--- End of stack trace from previous location where exception was thrown ---
   at System.Runtime.ExceptionServices.ExceptionDispatchInfo.Throw()
   at System.Runtime.CompilerServices.TaskAwaiter.ThrowForNonSuccess(Task task)
   at System.Runtime.CompilerServices.TaskAwaiter.HandleNonSuccessAndDebuggerNotification(Task task)
   at Amazon.Runtime.Internal.CallbackHandler.<InvokeAsync>d__9`1.MoveNext()
--- End of stack trace from previous location where exception was thrown ---
   at System.Runtime.ExceptionServices.ExceptionDispatchInfo.Throw()
   at System.Runtime.CompilerServices.TaskAwaiter.ThrowForNonSuccess(Task task)
   at System.Runtime.CompilerServices.TaskAwaiter.HandleNonSuccessAndDebuggerNotification(Task task)
   at Amazon.Runtime.Internal.CallbackHandler.<InvokeAsync>d__9`1.MoveNext()
--- End of stack trace from previous location where exception was thrown ---
   at System.Runtime.ExceptionServices.ExceptionDispatchInfo.Throw()
   at System.Runtime.CompilerServices.TaskAwaiter.ThrowForNonSuccess(Task task)
   at System.Runtime.CompilerServices.TaskAwaiter.HandleNonSuccessAndDebuggerNotification(Task task)
   at Amazon.S3.Internal.AmazonS3ExceptionHandler.<InvokeAsync>d__1`1.MoveNext()
--- End of stack trace from previous location where exception was thrown ---
   at System.Runtime.ExceptionServices.ExceptionDispatchInfo.Throw()
   at System.Runtime.CompilerServices.TaskAwaiter.ThrowForNonSuccess(Task task)
   at System.Runtime.CompilerServices.TaskAwaiter.HandleNonSuccessAndDebuggerNotification(Task task)
   at Amazon.Runtime.Internal.ErrorCallbackHandler.<InvokeAsync>d__5`1.MoveNext()
--- End of stack trace from previous location where exception was thrown ---
   at System.Runtime.ExceptionServices.ExceptionDispatchInfo.Throw()
   at System.Runtime.CompilerServices.TaskAwaiter.ThrowForNonSuccess(Task task)
   at System.Runtime.CompilerServices.TaskAwaiter.HandleNonSuccessAndDebuggerNotification(Task task)
   at Amazon.Runtime.Internal.MetricsHandler.<InvokeAsync>d__1`1.MoveNext()
--- End of stack trace from previous location where exception was thrown ---
   at System.Runtime.ExceptionServices.ExceptionDispatchInfo.Throw()
   at System.Runtime.CompilerServices.TaskAwaiter.ThrowForNonSuccess(Task task)
   at System.Runtime.CompilerServices.TaskAwaiter.HandleNonSuccessAndDebuggerNotification(Task task)
   at CKSource.FileSystem.Amazon.AmazonStorage.<GetFileInfosInternalAsync>d__29.MoveNext()
--- End of stack trace from previous location where exception was thrown ---
   at System.Runtime.ExceptionServices.ExceptionDispatchInfo.Throw()
   at System.Runtime.CompilerServices.TaskAwaiter.ThrowForNonSuccess(Task task)
   at System.Runtime.CompilerServices.TaskAwaiter.HandleNonSuccessAndDebuggerNotification(Task task)
   at CKSource.CKFinder.Connector.Core.Nodes.Folder.<ListFilesAsync>d__12.MoveNext()
--- End of stack trace from previous location where exception was thrown ---
   at System.Runtime.ExceptionServices.ExceptionDispatchInfo.Throw()
   at System.Runtime.CompilerServices.TaskAwaiter.ThrowForNonSuccess(Task task)
   at System.Runtime.CompilerServices.TaskAwaiter.HandleNonSuccessAndDebuggerNotification(Task task)
   at CKSource.CKFinder.Connector.Core.Commands.GetFiles.GetFilesCommandImpl.<ExecuteAsync>d__5.MoveNext()
--- End of stack trace from previous location where exception was thrown ---
   at System.Runtime.ExceptionServices.ExceptionDispatchInfo.Throw()
   at System.Runtime.CompilerServices.TaskAwaiter.ThrowForNonSuccess(Task task)
   at System.Runtime.CompilerServices.TaskAwaiter.HandleNonSuccessAndDebuggerNotification(Task task)
   at CKSource.CKFinder.Connector.Core.CommandHandler.<ExecuteAsync>d__12.MoveNext()
System.Net.WebException: The request was aborted: The request was canceled.
   at System.Net.HttpWebRequest.BeginGetResponse(AsyncCallback callback, Object state)
   at System.Threading.Tasks.TaskFactory`1.FromAsyncImpl(Func`3 beginMethod, Func`2 endFunction, Action`1 endAction, Object state, TaskCreationOptions creationOptions)
   at System.Net.WebRequest.<GetResponseAsync>b__78_1()
   at System.Threading.Tasks.Task`1.InnerInvoke()
   at System.Threading.Tasks.Task.Execute()
--- End of stack trace from previous location where exception was thrown ---
   at System.Runtime.ExceptionServices.ExceptionDispatchInfo.Throw()
   at System.Runtime.CompilerServices.TaskAwaiter.HandleNonSuccessAndDebuggerNotification(Task task)
   at Amazon.Runtime.Internal.HttpRequest.<GetResponseAsync>d__16.MoveNext()    at System.Net.HttpWebRequest.BeginGetResponse(AsyncCallback callback, Object state)
   at System.Threading.Tasks.TaskFactory`1.FromAsyncImpl(Func`3 beginMethod, Func`2 endFunction, Action`1 endAction, Object state, TaskCreationOptions creationOptions)
   at System.Net.WebRequest.<GetResponseAsync>b__78_1()
   at System.Threading.Tasks.Task`1.InnerInvoke()
   at System.Threading.Tasks.Task.Execute()
--- End of stack trace from previous location where exception was thrown ---
   at System.Runtime.ExceptionServices.ExceptionDispatchInfo.Throw()
   at System.Runtime.CompilerServices.TaskAwaiter.HandleNonSuccessAndDebuggerNotification(Task task)
   at Amazon.Runtime.Internal.HttpRequest.<GetResponseAsync>d__16.MoveNext()
Fatal | CKSource.CKFinder.Connector.Core.CommandHandler | 2019-03-07 11:56:25.7293 | An unknown error has occured during execution of Proxy command.| System.ObjectDisposedException: Cannot access a disposed object.
Object name: 'Amazon.S3.AmazonS3Client'.
   at Amazon.Runtime.AmazonServiceClient.ThrowIfDisposed()
   at Amazon.Runtime.AmazonServiceClient.InvokeAsync[TRequest,TResponse](TRequest request, IMarshaller`2 marshaller, ResponseUnmarshaller unmarshaller, CancellationToken cancellationToken)
   at Amazon.S3.AmazonS3Client.GetObjectMetadataAsync(GetObjectMetadataRequest request, CancellationToken cancellationToken)
   at CKSource.FileSystem.Amazon.AmazonFileInfo.<LoadAsync>d__6.MoveNext()
--- End of stack trace from previous location where exception was thrown ---
   at System.Runtime.ExceptionServices.ExceptionDispatchInfo.Throw()
   at System.Runtime.CompilerServices.TaskAwaiter.HandleNonSuccessAndDebuggerNotification(Task task)
   at CKSource.FileSystem.FileInfo.<GetMimeType>d__21.MoveNext()
--- End of stack trace from previous location where exception was thrown ---
   at System.Runtime.ExceptionServices.ExceptionDispatchInfo.Throw()
   at System.Runtime.CompilerServices.TaskAwaiter.HandleNonSuccessAndDebuggerNotification(Task task)
   at CKSource.CKFinder.Connector.Core.Commands.Proxy.ProxyCommandImpl.<ExecuteAsync>d__9.MoveNext()
--- End of stack trace from previous location where exception was thrown ---
   at System.Runtime.ExceptionServices.ExceptionDispatchInfo.Throw()
   at System.Runtime.CompilerServices.TaskAwaiter.HandleNonSuccessAndDebuggerNotification(Task task)
   at CKSource.CKFinder.Connector.Core.CommandHandler.<ExecuteAsync>d__12.MoveNext()    at Amazon.Runtime.AmazonServiceClient.ThrowIfDisposed()
   at Amazon.Runtime.AmazonServiceClient.InvokeAsync[TRequest,TResponse](TRequest request, IMarshaller`2 marshaller, ResponseUnmarshaller unmarshaller, CancellationToken cancellationToken)
   at Amazon.S3.AmazonS3Client.GetObjectMetadataAsync(GetObjectMetadataRequest request, CancellationToken cancellationToken)
   at CKSource.FileSystem.Amazon.AmazonFileInfo.<LoadAsync>d__6.MoveNext()
--- End of stack trace from previous location where exception was thrown ---
   at System.Runtime.ExceptionServices.ExceptionDispatchInfo.Throw()
   at System.Runtime.CompilerServices.TaskAwaiter.HandleNonSuccessAndDebuggerNotification(Task task)
   at CKSource.FileSystem.FileInfo.<GetMimeType>d__21.MoveNext()
--- End of stack trace from previous location where exception was thrown ---
   at System.Runtime.ExceptionServices.ExceptionDispatchInfo.Throw()
   at System.Runtime.CompilerServices.TaskAwaiter.HandleNonSuccessAndDebuggerNotification(Task task)
   at CKSource.CKFinder.Connector.Core.Commands.Proxy.ProxyCommandImpl.<ExecuteAsync>d__9.MoveNext()
--- End of stack trace from previous location where exception was thrown ---
   at System.Runtime.ExceptionServices.ExceptionDispatchInfo.Throw()
   at System.Runtime.CompilerServices.TaskAwaiter.HandleNonSuccessAndDebuggerNotification(Task task)
   at CKSource.CKFinder.Connector.Core.CommandHandler.<ExecuteAsync>d__12.MoveNext()
Fatal | CKSource.CKFinder.Connector.Core.CommandHandler | 2019-03-07 11:57:01.8729 | An unknown error has occured during execution of Proxy command.| System.ObjectDisposedException: Cannot access a disposed object.
Object name: 'Amazon.S3.AmazonS3Client'.
   at Amazon.Runtime.AmazonServiceClient.ThrowIfDisposed()
   at Amazon.Runtime.AmazonServiceClient.InvokeAsync[TRequest,TResponse](TRequest request, IMarshaller`2 marshaller, ResponseUnmarshaller unmarshaller, CancellationToken cancellationToken)
   at Amazon.S3.AmazonS3Client.GetObjectMetadataAsync(GetObjectMetadataRequest request, CancellationToken cancellationToken)
   at CKSource.FileSystem.Amazon.AmazonFileInfo.<LoadAsync>d__6.MoveNext()
--- End of stack trace from previous location where exception was thrown ---
   at System.Runtime.ExceptionServices.ExceptionDispatchInfo.Throw()
   at System.Runtime.CompilerServices.TaskAwaiter.HandleNonSuccessAndDebuggerNotification(Task task)
   at CKSource.FileSystem.FileInfo.<GetMimeType>d__21.MoveNext()
--- End of stack trace from previous location where exception was thrown ---
   at System.Runtime.ExceptionServices.ExceptionDispatchInfo.Throw()
   at System.Runtime.CompilerServices.TaskAwaiter.HandleNonSuccessAndDebuggerNotification(Task task)
   at CKSource.CKFinder.Connector.Core.Commands.Proxy.ProxyCommandImpl.<ExecuteAsync>d__9.MoveNext()
--- End of stack trace from previous location where exception was thrown ---
   at System.Runtime.ExceptionServices.ExceptionDispatchInfo.Throw()
   at System.Runtime.CompilerServices.TaskAwaiter.HandleNonSuccessAndDebuggerNotification(Task task)
   at CKSource.CKFinder.Connector.Core.CommandHandler.<ExecuteAsync>d__12.MoveNext()    at Amazon.Runtime.AmazonServiceClient.ThrowIfDisposed()
   at Amazon.Runtime.AmazonServiceClient.InvokeAsync[TRequest,TResponse](TRequest request, IMarshaller`2 marshaller, ResponseUnmarshaller unmarshaller, CancellationToken cancellationToken)
   at Amazon.S3.AmazonS3Client.GetObjectMetadataAsync(GetObjectMetadataRequest request, CancellationToken cancellationToken)
   at CKSource.FileSystem.Amazon.AmazonFileInfo.<LoadAsync>d__6.MoveNext()
--- End of stack trace from previous location where exception was thrown ---
   at System.Runtime.ExceptionServices.ExceptionDispatchInfo.Throw()
   at System.Runtime.CompilerServices.TaskAwaiter.HandleNonSuccessAndDebuggerNotification(Task task)
   at CKSource.FileSystem.FileInfo.<GetMimeType>d__21.MoveNext()
--- End of stack trace from previous location where exception was thrown ---
   at System.Runtime.ExceptionServices.ExceptionDispatchInfo.Throw()
   at System.Runtime.CompilerServices.TaskAwaiter.HandleNonSuccessAndDebuggerNotification(Task task)
   at CKSource.CKFinder.Connector.Core.Commands.Proxy.ProxyCommandImpl.<ExecuteAsync>d__9.MoveNext()
--- End of stack trace from previous location where exception was thrown ---
   at System.Runtime.ExceptionServices.ExceptionDispatchInfo.Throw()
   at System.Runtime.CompilerServices.TaskAwaiter.HandleNonSuccessAndDebuggerNotification(Task task)
   at CKSource.CKFinder.Connector.Core.CommandHandler.<ExecuteAsync>d__12.MoveNext()
Fatal | CKSource.CKFinder.Connector.Core.CommandHandler | 2019-03-07 11:59:08.2384 | An unknown error has occured during execution of Proxy command.| System.ObjectDisposedException: Cannot access a disposed object.
Object name: 'Amazon.S3.AmazonS3Client'.
   at Amazon.Runtime.AmazonServiceClient.ThrowIfDisposed()
   at Amazon.Runtime.AmazonServiceClient.InvokeAsync[TRequest,TResponse](TRequest request, IMarshaller`2 marshaller, ResponseUnmarshaller unmarshaller, CancellationToken cancellationToken)
   at Amazon.S3.AmazonS3Client.GetObjectMetadataAsync(GetObjectMetadataRequest request, CancellationToken cancellationToken)
   at CKSource.FileSystem.Amazon.AmazonFileInfo.<LoadAsync>d__6.MoveNext()
--- End of stack trace from previous location where exception was thrown ---
   at System.Runtime.ExceptionServices.ExceptionDispatchInfo.Throw()
   at System.Runtime.CompilerServices.TaskAwaiter.HandleNonSuccessAndDebuggerNotification(Task task)
   at CKSource.FileSystem.FileInfo.<GetMimeType>d__21.MoveNext()
--- End of stack trace from previous location where exception was thrown ---
   at System.Runtime.ExceptionServices.ExceptionDispatchInfo.Throw()
   at System.Runtime.CompilerServices.TaskAwaiter.HandleNonSuccessAndDebuggerNotification(Task task)
   at CKSource.CKFinder.Connector.Core.Commands.Proxy.ProxyCommandImpl.<ExecuteAsync>d__9.MoveNext()
--- End of stack trace from previous location where exception was thrown ---
   at System.Runtime.ExceptionServices.ExceptionDispatchInfo.Throw()
   at System.Runtime.CompilerServices.TaskAwaiter.HandleNonSuccessAndDebuggerNotification(Task task)
   at CKSource.CKFinder.Connector.Core.CommandHandler.<ExecuteAsync>d__12.MoveNext()    at Amazon.Runtime.AmazonServiceClient.ThrowIfDisposed()
   at Amazon.Runtime.AmazonServiceClient.InvokeAsync[TRequest,TResponse](TRequest request, IMarshaller`2 marshaller, ResponseUnmarshaller unmarshaller, CancellationToken cancellationToken)
   at Amazon.S3.AmazonS3Client.GetObjectMetadataAsync(GetObjectMetadataRequest request, CancellationToken cancellationToken)
   at CKSource.FileSystem.Amazon.AmazonFileInfo.<LoadAsync>d__6.MoveNext()
--- End of stack trace from previous location where exception was thrown ---
   at System.Runtime.ExceptionServices.ExceptionDispatchInfo.Throw()
   at System.Runtime.CompilerServices.TaskAwaiter.HandleNonSuccessAndDebuggerNotification(Task task)
   at CKSource.FileSystem.FileInfo.<GetMimeType>d__21.MoveNext()
--- End of stack trace from previous location where exception was thrown ---
   at System.Runtime.ExceptionServices.ExceptionDispatchInfo.Throw()
   at System.Runtime.CompilerServices.TaskAwaiter.HandleNonSuccessAndDebuggerNotification(Task task)
   at CKSource.CKFinder.Connector.Core.Commands.Proxy.ProxyCommandImpl.<ExecuteAsync>d__9.MoveNext()
--- End of stack trace from previous location where exception was thrown ---
   at System.Runtime.ExceptionServices.ExceptionDispatchInfo.Throw()
   at System.Runtime.CompilerServices.TaskAwaiter.HandleNonSuccessAndDebuggerNotification(Task task)
   at CKSource.CKFinder.Connector.Core.CommandHandler.<ExecuteAsync>d__12.MoveNext()
Fatal | CKSource.CKFinder.Connector.Core.CommandHandler | 2019-03-07 12:01:22.6894 | An unknown error has occured during execution of Proxy command.| System.ObjectDisposedException: Cannot access a disposed object.
Object name: 'Amazon.S3.AmazonS3Client'.
   at Amazon.Runtime.AmazonServiceClient.ThrowIfDisposed()
   at Amazon.Runtime.AmazonServiceClient.InvokeAsync[TRequest,TResponse](TRequest request, IMarshaller`2 marshaller, ResponseUnmarshaller unmarshaller, CancellationToken cancellationToken)
   at Amazon.S3.AmazonS3Client.GetObjectMetadataAsync(GetObjectMetadataRequest request, CancellationToken cancellationToken)
   at CKSource.FileSystem.Amazon.AmazonFileInfo.<LoadAsync>d__6.MoveNext()
--- End of stack trace from previous location where exception was thrown ---
   at System.Runtime.ExceptionServices.ExceptionDispatchInfo.Throw()
   at System.Runtime.CompilerServices.TaskAwaiter.HandleNonSuccessAndDebuggerNotification(Task task)
   at CKSource.FileSystem.FileInfo.<GetMimeType>d__21.MoveNext()
--- End of stack trace from previous location where exception was thrown ---
   at System.Runtime.ExceptionServices.ExceptionDispatchInfo.Throw()
   at System.Runtime.CompilerServices.TaskAwaiter.HandleNonSuccessAndDebuggerNotification(Task task)
   at CKSource.CKFinder.Connector.Core.Commands.Proxy.ProxyCommandImpl.<ExecuteAsync>d__9.MoveNext()
--- End of stack trace from previous location where exception was thrown ---
   at System.Runtime.ExceptionServices.ExceptionDispatchInfo.Throw()
   at System.Runtime.CompilerServices.TaskAwaiter.HandleNonSuccessAndDebuggerNotification(Task task)
   at CKSource.CKFinder.Connector.Core.CommandHandler.<ExecuteAsync>d__12.MoveNext()    at Amazon.Runtime.AmazonServiceClient.ThrowIfDisposed()
   at Amazon.Runtime.AmazonServiceClient.InvokeAsync[TRequest,TResponse](TRequest request, IMarshaller`2 marshaller, ResponseUnmarshaller unmarshaller, CancellationToken cancellationToken)
   at Amazon.S3.AmazonS3Client.GetObjectMetadataAsync(GetObjectMetadataRequest request, CancellationToken cancellationToken)
   at CKSource.FileSystem.Amazon.AmazonFileInfo.<LoadAsync>d__6.MoveNext()
--- End of stack trace from previous location where exception was thrown ---
   at System.Runtime.ExceptionServices.ExceptionDispatchInfo.Throw()
   at System.Runtime.CompilerServices.TaskAwaiter.HandleNonSuccessAndDebuggerNotification(Task task)
   at CKSource.FileSystem.FileInfo.<GetMimeType>d__21.MoveNext()
--- End of stack trace from previous location where exception was thrown ---
   at System.Runtime.ExceptionServices.ExceptionDispatchInfo.Throw()
   at System.Runtime.CompilerServices.TaskAwaiter.HandleNonSuccessAndDebuggerNotification(Task task)
   at CKSource.CKFinder.Connector.Core.Commands.Proxy.ProxyCommandImpl.<ExecuteAsync>d__9.MoveNext()
--- End of stack trace from previous location where exception was thrown ---
   at System.Runtime.ExceptionServices.ExceptionDispatchInfo.Throw()
   at System.Runtime.CompilerServices.TaskAwaiter.HandleNonSuccessAndDebuggerNotification(Task task)
   at CKSource.CKFinder.Connector.Core.CommandHandler.<ExecuteAsync>d__12.MoveNext()
Fatal | CKSource.CKFinder.Connector.Core.CommandHandler | 2019-03-07 12:03:08.1500 | An unknown error has occured during execution of Proxy command.| System.ObjectDisposedException: Cannot access a disposed object.
Object name: 'Amazon.S3.AmazonS3Client'.
   at Amazon.Runtime.AmazonServiceClient.ThrowIfDisposed()
   at Amazon.Runtime.AmazonServiceClient.InvokeAsync[TRequest,TResponse](TRequest request, IMarshaller`2 marshaller, ResponseUnmarshaller unmarshaller, CancellationToken cancellationToken)
   at Amazon.S3.AmazonS3Client.GetObjectMetadataAsync(GetObjectMetadataRequest request, CancellationToken cancellationToken)
   at CKSource.FileSystem.Amazon.AmazonFileInfo.<LoadAsync>d__6.MoveNext()
--- End of stack trace from previous location where exception was thrown ---
   at System.Runtime.ExceptionServices.ExceptionDispatchInfo.Throw()
   at System.Runtime.CompilerServices.TaskAwaiter.HandleNonSuccessAndDebuggerNotification(Task task)
   at CKSource.FileSystem.FileInfo.<GetMimeType>d__21.MoveNext()
--- End of stack trace from previous location where exception was thrown ---
   at System.Runtime.ExceptionServices.ExceptionDispatchInfo.Throw()
   at System.Runtime.CompilerServices.TaskAwaiter.HandleNonSuccessAndDebuggerNotification(Task task)
   at CKSource.CKFinder.Connector.Core.Commands.Proxy.ProxyCommandImpl.<ExecuteAsync>d__9.MoveNext()
--- End of stack trace from previous location where exception was thrown ---
   at System.Runtime.ExceptionServices.ExceptionDispatchInfo.Throw()
   at System.Runtime.CompilerServices.TaskAwaiter.HandleNonSuccessAndDebuggerNotification(Task task)
   at CKSource.CKFinder.Connector.Core.CommandHandler.<ExecuteAsync>d__12.MoveNext()    at Amazon.Runtime.AmazonServiceClient.ThrowIfDisposed()
   at Amazon.Runtime.AmazonServiceClient.InvokeAsync[TRequest,TResponse](TRequest request, IMarshaller`2 marshaller, ResponseUnmarshaller unmarshaller, CancellationToken cancellationToken)
   at Amazon.S3.AmazonS3Client.GetObjectMetadataAsync(GetObjectMetadataRequest request, CancellationToken cancellationToken)
   at CKSource.FileSystem.Amazon.AmazonFileInfo.<LoadAsync>d__6.MoveNext()
--- End of stack trace from previous location where exception was thrown ---
   at System.Runtime.ExceptionServices.ExceptionDispatchInfo.Throw()
   at System.Runtime.CompilerServices.TaskAwaiter.HandleNonSuccessAndDebuggerNotification(Task task)
   at CKSource.FileSystem.FileInfo.<GetMimeType>d__21.MoveNext()
--- End of stack trace from previous location where exception was thrown ---
   at System.Runtime.ExceptionServices.ExceptionDispatchInfo.Throw()
   at System.Runtime.CompilerServices.TaskAwaiter.HandleNonSuccessAndDebuggerNotification(Task task)
   at CKSource.CKFinder.Connector.Core.Commands.Proxy.ProxyCommandImpl.<ExecuteAsync>d__9.MoveNext()
--- End of stack trace from previous location where exception was thrown ---
   at System.Runtime.ExceptionServices.ExceptionDispatchInfo.Throw()
   at System.Runtime.CompilerServices.TaskAwaiter.HandleNonSuccessAndDebuggerNotification(Task task)
   at CKSource.CKFinder.Connector.Core.CommandHandler.<ExecuteAsync>d__12.MoveNext()
Fatal | CKSource.CKFinder.Connector.Core.CommandHandler | 2019-03-07 12:06:36.2602 | An unknown error has occured during execution of Proxy command.| System.ObjectDisposedException: Cannot access a disposed object.
Object name: 'Amazon.S3.AmazonS3Client'.
   at Amazon.Runtime.AmazonServiceClient.ThrowIfDisposed()
   at Amazon.Runtime.AmazonServiceClient.InvokeAsync[TRequest,TResponse](TRequest request, IMarshaller`2 marshaller, ResponseUnmarshaller unmarshaller, CancellationToken cancellationToken)
   at Amazon.S3.AmazonS3Client.GetObjectMetadataAsync(GetObjectMetadataRequest request, CancellationToken cancellationToken)
   at CKSource.FileSystem.Amazon.AmazonFileInfo.<LoadAsync>d__6.MoveNext()
--- End of stack trace from previous location where exception was thrown ---
   at System.Runtime.ExceptionServices.ExceptionDispatchInfo.Throw()
   at System.Runtime.CompilerServices.TaskAwaiter.HandleNonSuccessAndDebuggerNotification(Task task)
   at CKSource.FileSystem.FileInfo.<GetMimeType>d__21.MoveNext()
--- End of stack trace from previous location where exception was thrown ---
   at System.Runtime.ExceptionServices.ExceptionDispatchInfo.Throw()
   at System.Runtime.CompilerServices.TaskAwaiter.HandleNonSuccessAndDebuggerNotification(Task task)
   at CKSource.CKFinder.Connector.Core.Commands.Proxy.ProxyCommandImpl.<ExecuteAsync>d__9.MoveNext()
--- End of stack trace from previous location where exception was thrown ---
   at System.Runtime.ExceptionServices.ExceptionDispatchInfo.Throw()
   at System.Runtime.CompilerServices.TaskAwaiter.HandleNonSuccessAndDebuggerNotification(Task task)
   at CKSource.CKFinder.Connector.Core.CommandHandler.<ExecuteAsync>d__12.MoveNext()    at Amazon.Runtime.AmazonServiceClient.ThrowIfDisposed()
   at Amazon.Runtime.AmazonServiceClient.InvokeAsync[TRequest,TResponse](TRequest request, IMarshaller`2 marshaller, ResponseUnmarshaller unmarshaller, CancellationToken cancellationToken)
   at Amazon.S3.AmazonS3Client.GetObjectMetadataAsync(GetObjectMetadataRequest request, CancellationToken cancellationToken)
   at CKSource.FileSystem.Amazon.AmazonFileInfo.<LoadAsync>d__6.MoveNext()
--- End of stack trace from previous location where exception was thrown ---
   at System.Runtime.ExceptionServices.ExceptionDispatchInfo.Throw()
   at System.Runtime.CompilerServices.TaskAwaiter.HandleNonSuccessAndDebuggerNotification(Task task)
   at CKSource.FileSystem.FileInfo.<GetMimeType>d__21.MoveNext()
--- End of stack trace from previous location where exception was thrown ---
   at System.Runtime.ExceptionServices.ExceptionDispatchInfo.Throw()
   at System.Runtime.CompilerServices.TaskAwaiter.HandleNonSuccessAndDebuggerNotification(Task task)
   at CKSource.CKFinder.Connector.Core.Commands.Proxy.ProxyCommandImpl.<ExecuteAsync>d__9.MoveNext()
--- End of stack trace from previous location where exception was thrown ---
   at System.Runtime.ExceptionServices.ExceptionDispatchInfo.Throw()
   at System.Runtime.CompilerServices.TaskAwaiter.HandleNonSuccessAndDebuggerNotification(Task task)
   at CKSource.CKFinder.Connector.Core.CommandHandler.<ExecuteAsync>d__12.MoveNext()
Fatal | CKSource.CKFinder.Connector.Core.CommandHandler | 2019-03-07 12:08:07.9085 | An unknown error has occured during execution of Proxy command.| System.ObjectDisposedException: Cannot access a disposed object.
Object name: 'Amazon.S3.AmazonS3Client'.
   at Amazon.Runtime.AmazonServiceClient.ThrowIfDisposed()
   at Amazon.Runtime.AmazonServiceClient.InvokeAsync[TRequest,TResponse](TRequest request, IMarshaller`2 marshaller, ResponseUnmarshaller unmarshaller, CancellationToken cancellationToken)
   at Amazon.S3.AmazonS3Client.GetObjectMetadataAsync(GetObjectMetadataRequest request, CancellationToken cancellationToken)
   at CKSource.FileSystem.Amazon.AmazonFileInfo.<LoadAsync>d__6.MoveNext()
--- End of stack trace from previous location where exception was thrown ---
   at System.Runtime.ExceptionServices.ExceptionDispatchInfo.Throw()
   at System.Runtime.CompilerServices.TaskAwaiter.HandleNonSuccessAndDebuggerNotification(Task task)
   at CKSource.FileSystem.FileInfo.<GetMimeType>d__21.MoveNext()
--- End of stack trace from previous location where exception was thrown ---
   at System.Runtime.ExceptionServices.ExceptionDispatchInfo.Throw()
   at System.Runtime.CompilerServices.TaskAwaiter.HandleNonSuccessAndDebuggerNotification(Task task)
   at CKSource.CKFinder.Connector.Core.Commands.Proxy.ProxyCommandImpl.<ExecuteAsync>d__9.MoveNext()
--- End of stack trace from previous location where exception was thrown ---
   at System.Runtime.ExceptionServices.ExceptionDispatchInfo.Throw()
   at System.Runtime.CompilerServices.TaskAwaiter.HandleNonSuccessAndDebuggerNotification(Task task)
   at CKSource.CKFinder.Connector.Core.CommandHandler.<ExecuteAsync>d__12.MoveNext()    at Amazon.Runtime.AmazonServiceClient.ThrowIfDisposed()
   at Amazon.Runtime.AmazonServiceClient.InvokeAsync[TRequest,TResponse](TRequest request, IMarshaller`2 marshaller, ResponseUnmarshaller unmarshaller, CancellationToken cancellationToken)
   at Amazon.S3.AmazonS3Client.GetObjectMetadataAsync(GetObjectMetadataRequest request, CancellationToken cancellationToken)
   at CKSource.FileSystem.Amazon.AmazonFileInfo.<LoadAsync>d__6.MoveNext()
--- End of stack trace from previous location where exception was thrown ---
   at System.Runtime.ExceptionServices.ExceptionDispatchInfo.Throw()
   at System.Runtime.CompilerServices.TaskAwaiter.HandleNonSuccessAndDebuggerNotification(Task task)
   at CKSource.FileSystem.FileInfo.<GetMimeType>d__21.MoveNext()
--- End of stack trace from previous location where exception was thrown ---
   at System.Runtime.ExceptionServices.ExceptionDispatchInfo.Throw()
   at System.Runtime.CompilerServices.TaskAwaiter.HandleNonSuccessAndDebuggerNotification(Task task)
   at CKSource.CKFinder.Connector.Core.Commands.Proxy.ProxyCommandImpl.<ExecuteAsync>d__9.MoveNext()
--- End of stack trace from previous location where exception was thrown ---
   at System.Runtime.ExceptionServices.ExceptionDispatchInfo.Throw()
   at System.Runtime.CompilerServices.TaskAwaiter.HandleNonSuccessAndDebuggerNotification(Task task)
   at CKSource.CKFinder.Connector.Core.CommandHandler.<ExecuteAsync>d__12.MoveNext()
Fatal | CKSource.CKFinder.Connector.Core.CommandHandler | 2019-03-07 12:21:59.3546 | An unknown error has occured during execution of Proxy command.| System.ObjectDisposedException: Cannot access a disposed object.
Object name: 'Amazon.S3.AmazonS3Client'.
   at Amazon.Runtime.AmazonServiceClient.ThrowIfDisposed()
   at Amazon.Runtime.AmazonServiceClient.InvokeAsync[TRequest,TResponse](TRequest request, IMarshaller`2 marshaller, ResponseUnmarshaller unmarshaller, CancellationToken cancellationToken)
   at Amazon.S3.AmazonS3Client.GetObjectMetadataAsync(GetObjectMetadataRequest request, CancellationToken cancellationToken)
   at CKSource.FileSystem.Amazon.AmazonFileInfo.<LoadAsync>d__6.MoveNext()
--- End of stack trace from previous location where exception was thrown ---
   at System.Runtime.ExceptionServices.ExceptionDispatchInfo.Throw()
   at System.Runtime.CompilerServices.TaskAwaiter.HandleNonSuccessAndDebuggerNotification(Task task)
   at CKSource.FileSystem.FileInfo.<GetMimeType>d__21.MoveNext()
--- End of stack trace from previous location where exception was thrown ---
   at System.Runtime.ExceptionServices.ExceptionDispatchInfo.Throw()
   at System.Runtime.CompilerServices.TaskAwaiter.HandleNonSuccessAndDebuggerNotification(Task task)
   at CKSource.CKFinder.Connector.Core.Commands.Proxy.ProxyCommandImpl.<ExecuteAsync>d__9.MoveNext()
--- End of stack trace from previous location where exception was thrown ---
   at System.Runtime.ExceptionServices.ExceptionDispatchInfo.Throw()
   at System.Runtime.CompilerServices.TaskAwaiter.HandleNonSuccessAndDebuggerNotification(Task task)
   at CKSource.CKFinder.Connector.Core.CommandHandler.<ExecuteAsync>d__12.MoveNext()    at Amazon.Runtime.AmazonServiceClient.ThrowIfDisposed()
   at Amazon.Runtime.AmazonServiceClient.InvokeAsync[TRequest,TResponse](TRequest request, IMarshaller`2 marshaller, ResponseUnmarshaller unmarshaller, CancellationToken cancellationToken)
   at Amazon.S3.AmazonS3Client.GetObjectMetadataAsync(GetObjectMetadataRequest request, CancellationToken cancellationToken)
   at CKSource.FileSystem.Amazon.AmazonFileInfo.<LoadAsync>d__6.MoveNext()
--- End of stack trace from previous location where exception was thrown ---
   at System.Runtime.ExceptionServices.ExceptionDispatchInfo.Throw()
   at System.Runtime.CompilerServices.TaskAwaiter.HandleNonSuccessAndDebuggerNotification(Task task)
   at CKSource.FileSystem.FileInfo.<GetMimeType>d__21.MoveNext()
--- End of stack trace from previous location where exception was thrown ---
   at System.Runtime.ExceptionServices.ExceptionDispatchInfo.Throw()
   at System.Runtime.CompilerServices.TaskAwaiter.HandleNonSuccessAndDebuggerNotification(Task task)
   at CKSource.CKFinder.Connector.Core.Commands.Proxy.ProxyCommandImpl.<ExecuteAsync>d__9.MoveNext()
--- End of stack trace from previous location where exception was thrown ---
   at System.Runtime.ExceptionServices.ExceptionDispatchInfo.Throw()
   at System.Runtime.CompilerServices.TaskAwaiter.HandleNonSuccessAndDebuggerNotification(Task task)
   at CKSource.CKFinder.Connector.Core.CommandHandler.<ExecuteAsync>d__12.MoveNext()
Fatal | CKSource.CKFinder.Connector.Core.CommandHandler | 2019-03-07 12:22:06.6035 | An unknown error has occured during execution of Proxy command.| System.ObjectDisposedException: Cannot access a disposed object.
Object name: 'Amazon.S3.AmazonS3Client'.
   at Amazon.Runtime.AmazonServiceClient.ThrowIfDisposed()
   at Amazon.Runtime.AmazonServiceClient.InvokeAsync[TRequest,TResponse](TRequest request, IMarshaller`2 marshaller, ResponseUnmarshaller unmarshaller, CancellationToken cancellationToken)
   at Amazon.S3.AmazonS3Client.GetObjectMetadataAsync(GetObjectMetadataRequest request, CancellationToken cancellationToken)
   at CKSource.FileSystem.Amazon.AmazonFileInfo.<LoadAsync>d__6.MoveNext()
--- End of stack trace from previous location where exception was thrown ---
   at System.Runtime.ExceptionServices.ExceptionDispatchInfo.Throw()
   at System.Runtime.CompilerServices.TaskAwaiter.HandleNonSuccessAndDebuggerNotification(Task task)
   at CKSource.FileSystem.FileInfo.<GetMimeType>d__21.MoveNext()
--- End of stack trace from previous location where exception was thrown ---
   at System.Runtime.ExceptionServices.ExceptionDispatchInfo.Throw()
   at System.Runtime.CompilerServices.TaskAwaiter.HandleNonSuccessAndDebuggerNotification(Task task)
   at CKSource.CKFinder.Connector.Core.Commands.Proxy.ProxyCommandImpl.<ExecuteAsync>d__9.MoveNext()
--- End of stack trace from previous location where exception was thrown ---
   at System.Runtime.ExceptionServices.ExceptionDispatchInfo.Throw()
   at System.Runtime.CompilerServices.TaskAwaiter.HandleNonSuccessAndDebuggerNotification(Task task)
   at CKSource.CKFinder.Connector.Core.CommandHandler.<ExecuteAsync>d__12.MoveNext()    at Amazon.Runtime.AmazonServiceClient.ThrowIfDisposed()
   at Amazon.Runtime.AmazonServiceClient.InvokeAsync[TRequest,TResponse](TRequest request, IMarshaller`2 marshaller, ResponseUnmarshaller unmarshaller, CancellationToken cancellationToken)
   at Amazon.S3.AmazonS3Client.GetObjectMetadataAsync(GetObjectMetadataRequest request, CancellationToken cancellationToken)
   at CKSource.FileSystem.Amazon.AmazonFileInfo.<LoadAsync>d__6.MoveNext()
--- End of stack trace from previous location where exception was thrown ---
   at System.Runtime.ExceptionServices.ExceptionDispatchInfo.Throw()
   at System.Runtime.CompilerServices.TaskAwaiter.HandleNonSuccessAndDebuggerNotification(Task task)
   at CKSource.FileSystem.FileInfo.<GetMimeType>d__21.MoveNext()
--- End of stack trace from previous location where exception was thrown ---
   at System.Runtime.ExceptionServices.ExceptionDispatchInfo.Throw()
   at System.Runtime.CompilerServices.TaskAwaiter.HandleNonSuccessAndDebuggerNotification(Task task)
   at CKSource.CKFinder.Connector.Core.Commands.Proxy.ProxyCommandImpl.<ExecuteAsync>d__9.MoveNext()
--- End of stack trace from previous location where exception was thrown ---
   at System.Runtime.ExceptionServices.ExceptionDispatchInfo.Throw()
   at System.Runtime.CompilerServices.TaskAwaiter.HandleNonSuccessAndDebuggerNotification(Task task)
   at CKSource.CKFinder.Connector.Core.CommandHandler.<ExecuteAsync>d__12.MoveNext()
Fatal | CKSource.CKFinder.Connector.Core.CommandHandler | 2019-03-07 12:22:21.5815 | An unknown error has occured during execution of Proxy command.| System.ObjectDisposedException: Cannot access a disposed object.
Object name: 'Amazon.S3.AmazonS3Client'.
   at Amazon.Runtime.AmazonServiceClient.ThrowIfDisposed()
   at Amazon.Runtime.AmazonServiceClient.InvokeAsync[TRequest,TResponse](TRequest request, IMarshaller`2 marshaller, ResponseUnmarshaller unmarshaller, CancellationToken cancellationToken)
   at Amazon.S3.AmazonS3Client.GetObjectMetadataAsync(GetObjectMetadataRequest request, CancellationToken cancellationToken)
   at CKSource.FileSystem.Amazon.AmazonFileInfo.<LoadAsync>d__6.MoveNext()
--- End of stack trace from previous location where exception was thrown ---
   at System.Runtime.ExceptionServices.ExceptionDispatchInfo.Throw()
   at System.Runtime.CompilerServices.TaskAwaiter.HandleNonSuccessAndDebuggerNotification(Task task)
   at CKSource.FileSystem.FileInfo.<GetMimeType>d__21.MoveNext()
--- End of stack trace from previous location where exception was thrown ---
   at System.Runtime.ExceptionServices.ExceptionDispatchInfo.Throw()
   at System.Runtime.CompilerServices.TaskAwaiter.HandleNonSuccessAndDebuggerNotification(Task task)
   at CKSource.CKFinder.Connector.Core.Commands.Proxy.ProxyCommandImpl.<ExecuteAsync>d__9.MoveNext()
--- End of stack trace from previous location where exception was thrown ---
   at System.Runtime.ExceptionServices.ExceptionDispatchInfo.Throw()
   at System.Runtime.CompilerServices.TaskAwaiter.HandleNonSuccessAndDebuggerNotification(Task task)
   at CKSource.CKFinder.Connector.Core.CommandHandler.<ExecuteAsync>d__12.MoveNext()    at Amazon.Runtime.AmazonServiceClient.ThrowIfDisposed()
   at Amazon.Runtime.AmazonServiceClient.InvokeAsync[TRequest,TResponse](TRequest request, IMarshaller`2 marshaller, ResponseUnmarshaller unmarshaller, CancellationToken cancellationToken)
   at Amazon.S3.AmazonS3Client.GetObjectMetadataAsync(GetObjectMetadataRequest request, CancellationToken cancellationToken)
   at CKSource.FileSystem.Amazon.AmazonFileInfo.<LoadAsync>d__6.MoveNext()
--- End of stack trace from previous location where exception was thrown ---
   at System.Runtime.ExceptionServices.ExceptionDispatchInfo.Throw()
   at System.Runtime.CompilerServices.TaskAwaiter.HandleNonSuccessAndDebuggerNotification(Task task)
   at CKSource.FileSystem.FileInfo.<GetMimeType>d__21.MoveNext()
--- End of stack trace from previous location where exception was thrown ---
   at System.Runtime.ExceptionServices.ExceptionDispatchInfo.Throw()
   at System.Runtime.CompilerServices.TaskAwaiter.HandleNonSuccessAndDebuggerNotification(Task task)
   at CKSource.CKFinder.Connector.Core.Commands.Proxy.ProxyCommandImpl.<ExecuteAsync>d__9.MoveNext()
--- End of stack trace from previous location where exception was thrown ---
   at System.Runtime.ExceptionServices.ExceptionDispatchInfo.Throw()
   at System.Runtime.CompilerServices.TaskAwaiter.HandleNonSuccessAndDebuggerNotification(Task task)
   at CKSource.CKFinder.Connector.Core.CommandHandler.<ExecuteAsync>d__12.MoveNext()
Fatal | CKSource.CKFinder.Connector.Core.CommandHandler | 2019-03-07 14:49:21.6928 | An unknown error has occured during execution of Proxy command.| System.ObjectDisposedException: Cannot access a disposed object.
Object name: 'Amazon.S3.AmazonS3Client'.
   at Amazon.Runtime.AmazonServiceClient.ThrowIfDisposed()
   at Amazon.Runtime.AmazonServiceClient.InvokeAsync[TRequest,TResponse](TRequest request, IMarshaller`2 marshaller, ResponseUnmarshaller unmarshaller, CancellationToken cancellationToken)
   at Amazon.S3.AmazonS3Client.GetObjectMetadataAsync(GetObjectMetadataRequest request, CancellationToken cancellationToken)
   at CKSource.FileSystem.Amazon.AmazonFileInfo.<LoadAsync>d__6.MoveNext()
--- End of stack trace from previous location where exception was thrown ---
   at System.Runtime.ExceptionServices.ExceptionDispatchInfo.Throw()
   at System.Runtime.CompilerServices.TaskAwaiter.HandleNonSuccessAndDebuggerNotification(Task task)
   at CKSource.FileSystem.FileInfo.<GetMimeType>d__21.MoveNext()
--- End of stack trace from previous location where exception was thrown ---
   at System.Runtime.ExceptionServices.ExceptionDispatchInfo.Throw()
   at System.Runtime.CompilerServices.TaskAwaiter.HandleNonSuccessAndDebuggerNotification(Task task)
   at CKSource.CKFinder.Connector.Core.Commands.Proxy.ProxyCommandImpl.<ExecuteAsync>d__9.MoveNext()
--- End of stack trace from previous location where exception was thrown ---
   at System.Runtime.ExceptionServices.ExceptionDispatchInfo.Throw()
   at System.Runtime.CompilerServices.TaskAwaiter.HandleNonSuccessAndDebuggerNotification(Task task)
   at CKSource.CKFinder.Connector.Core.CommandHandler.<ExecuteAsync>d__12.MoveNext()    at Amazon.Runtime.AmazonServiceClient.ThrowIfDisposed()
   at Amazon.Runtime.AmazonServiceClient.InvokeAsync[TRequest,TResponse](TRequest request, IMarshaller`2 marshaller, ResponseUnmarshaller unmarshaller, CancellationToken cancellationToken)
   at Amazon.S3.AmazonS3Client.GetObjectMetadataAsync(GetObjectMetadataRequest request, CancellationToken cancellationToken)
   at CKSource.FileSystem.Amazon.AmazonFileInfo.<LoadAsync>d__6.MoveNext()
--- End of stack trace from previous location where exception was thrown ---
   at System.Runtime.ExceptionServices.ExceptionDispatchInfo.Throw()
   at System.Runtime.CompilerServices.TaskAwaiter.HandleNonSuccessAndDebuggerNotification(Task task)
   at CKSource.FileSystem.FileInfo.<GetMimeType>d__21.MoveNext()
--- End of stack trace from previous location where exception was thrown ---
   at System.Runtime.ExceptionServices.ExceptionDispatchInfo.Throw()
   at System.Runtime.CompilerServices.TaskAwaiter.HandleNonSuccessAndDebuggerNotification(Task task)
   at CKSource.CKFinder.Connector.Core.Commands.Proxy.ProxyCommandImpl.<ExecuteAsync>d__9.MoveNext()
--- End of stack trace from previous location where exception was thrown ---
   at System.Runtime.ExceptionServices.ExceptionDispatchInfo.Throw()
   at System.Runtime.CompilerServices.TaskAwaiter.HandleNonSuccessAndDebuggerNotification(Task task)
   at CKSource.CKFinder.Connector.Core.CommandHandler.<ExecuteAsync>d__12.MoveNext()
